#VRML_SIM R2023b utf8

EXTERNPROTO "https://raw.githubusercontent.com/cyberbotics/webots/R2023a/projects/objects/backgrounds/protos/TexturedBackground.proto"
EXTERNPROTO "https://raw.githubusercontent.com/cyberbotics/webots/R2023a/projects/objects/backgrounds/protos/TexturedBackgroundLight.proto"
EXTERNPROTO "https://raw.githubusercontent.com/cyberbotics/webots/R2023b/projects/objects/factory/containers/protos/WoodenBox.proto"
EXTERNPROTO "https://raw.githubusercontent.com/cyberbotics/webots/R2023b/projects/robots/gctronic/e-puck/protos/E-puck.proto"
EXTERNPROTO "https://raw.githubusercontent.com/cyberbotics/webots/R2023b/projects/objects/floors/protos/RectangleArena.proto"

WorldInfo {
  basicTimeStep 16
}
Viewpoint {
  orientation -0.09490803449680396 0.08511218871794506 0.9918409047420833 1.6876898780918104
  position 0.13428220214605857 -1.0307989549106464 0.25575214130279705
}
TexturedBackground {
  texture "morning_cloudy_empty"
}
TexturedBackgroundLight {
}
WoodenBox {
  translation -2.3 0 0.76
  name "wooden box(1)"
  size 1.5 1.5 1.5
}
Solid {
  translation 0.88 2.31 0.58
  children [
    DEF Balletjeeee Shape {
      appearance PBRAppearance {
        baseColorMap ImageTexture {
          url [
            "../../../../../../Downloads/jpg_44-2.jpg"
          ]
        }
      }
      geometry Sphere {
        radius 0.5
      }
    }
  ]
  boundingObject DEF balleke Sphere {
    radius 0.5
  }
  physics Physics {
  }
}
Solid {
  translation 0 1.42 2.46
  children [
    USE Balletjeeee
  ]
  name "solid(1)"
  boundingObject USE balleke
  physics Physics {
    density -1
    mass 3
  }
}
Solid {
  translation -4.71 0 2.77
  rotation 0 1 0 -1.5707953071795862
  children [
    DEF G0 Group {
      children [
        Pose {
          translation 0 0 0.42
          children [
            Shape {
              geometry Sphere {
                radius 0.1
              }
            }
          ]
        }
        Pose {
          translation 0 0 -0.41
          children [
            Shape {
              geometry Sphere {
                radius 0.1
              }
            }
          ]
        }
        Shape {
          geometry Cylinder {
            height 0.8
            radius 0.02
          }
        }
      ]
    }
  ]
  name "solid(2)"
  boundingObject USE G0
  physics Physics {
    density -1
    mass 2
    centerOfMass [
      0 0 0.2
    ]
  }
}
RectangleArena {
  floorSize 20 20
  floorTileSize 3 3
  wallHeight 1.5
}
E-puck {
  translation 0 2.15 0
  controller "HiddeSkibidi"
}
Robot {
  translation 0 0 0.06
  children [
    DistanceSensor {
    }
    DEF BODY Shape {
      appearance PBRAppearance {
        baseColor 1 0 0
        metalness 0
      }
      geometry Box {
        size 0.2 0.1 0.05
      }
    }
    HingeJoint {
      jointParameters HingeJointParameters {
        axis 0 1 0
        anchor 0.05 0.06 0
      }
      device [
        RotationalMotor {
        }
      ]
      endPoint Solid {
        translation 0.05 0.06 0
        rotation 1 0 0 1.5707999856068915
        children [
          DEF WHEELSIZE Shape {
            appearance PBRAppearance {
              baseColor 0 1 0
              metalness 0
            }
            geometry Cylinder {
              height 0.02
              radius 0.05
            }
          }
        ]
        name "Wheel1"
        boundingObject USE WHEELSIZE
        physics DEF WheelPhysics Physics {
          density -1
          mass 1
        }
      }
    }
    HingeJoint {
      jointParameters HingeJointParameters {
        axis 0 1 0
        anchor 0.05 -0.06 0
      }
      device [
        RotationalMotor {
        }
      ]
      endPoint Solid {
        translation 0.05000001219645437 -0.05999995888231524 3.64022064517418e-06
        rotation 1 6.604073036319333e-09 -6.551384359806268e-09 1.5707999857592654
        children [
          USE WHEELSIZE
        ]
        name "Wheel2"
        boundingObject USE WHEELSIZE
        physics USE WheelPhysics
      }
    }
    HingeJoint {
      jointParameters HingeJointParameters {
        axis 0 1 0
        anchor -0.05 -0.06 0
      }
      device [
        RotationalMotor {
        }
      ]
      endPoint Solid {
        translation -0.05 -0.06 0
        rotation 1 0 0 1.5707999835202933
        children [
          USE WHEELSIZE
        ]
        name "Wheel3"
        boundingObject USE WHEELSIZE
        physics USE WheelPhysics
      }
    }
    HingeJoint {
      jointParameters HingeJointParameters {
        axis 0 1 0
        anchor -0.05 0.06 0
      }
      device [
        RotationalMotor {
        }
      ]
      endPoint Solid {
        translation -0.049999996851340836 0.060000021341082885 4.130467837359915e-06
        rotation 1 -5.0653910242930504e-09 5.119238130299488e-09 1.5707999882284158
        children [
          USE WHEELSIZE
        ]
        name "Wheel4"
        boundingObject USE WHEELSIZE
        physics USE WheelPhysics
      }
    }
  ]
  boundingObject USE BODY
  physics Physics {
  }
}
