#VRML_SIM R2023b utf8

EXTERNPROTO "https://raw.githubusercontent.com/cyberbotics/webots/R2023a/projects/objects/backgrounds/protos/TexturedBackground.proto"
EXTERNPROTO "https://raw.githubusercontent.com/cyberbotics/webots/R2023a/projects/objects/backgrounds/protos/TexturedBackgroundLight.proto"
EXTERNPROTO "https://raw.githubusercontent.com/cyberbotics/webots/R2023b/projects/objects/floors/protos/RectangleArena.proto"

WorldInfo {
  basicTimeStep 16
}
Viewpoint {
  orientation -0.5705728724325232 0.5544003665667234 0.605876910597179 2.077453578598804
  position -2.3235744422998 -1.4808630333892794 5.336382388656183
}
TexturedBackground {
  texture "morning_cloudy_empty"
}
TexturedBackgroundLight {
}
RectangleArena {
  floorSize 6.5 5
  floorTileSize 1 1
  wallHeight 1.5
}
Robot {
  translation -3 -2.26 0.06
  rotation 0 0 1 1.5708
  children [
    DistanceSensor {
    }
    DEF BODY Shape {
      appearance PBRAppearance {
        metalness 0
      }
      geometry Box {
        size 0.2 0.1 0.05
      }
    }
    HingeJoint {
      jointParameters HingeJointParameters {
        axis 0 1 0
        anchor 0.05 0.06 0
      }
      device [
        RotationalMotor {
          name "Wheel1"
        }
      ]
      endPoint Solid {
        translation 0.05 0.06 0
        rotation 1 0 0 1.5707999856068915
        children [
          DEF WHEELSIZE Shape {
            appearance PBRAppearance {
              baseColor 0 0 0
              metalness 0
            }
            geometry Cylinder {
              height 0.02
              radius 0.05
            }
          }
        ]
        name "Wheel1"
        boundingObject USE WHEELSIZE
        physics DEF WheelPhysics Physics {
          density -1
          mass 1
        }
      }
    }
    HingeJoint {
      jointParameters HingeJointParameters {
        axis 0 1 0
        anchor 0.05 -0.06 0
      }
      device [
        RotationalMotor {
          name "Wheel2"
        }
      ]
      endPoint Solid {
        translation 0.05000001219645437 -0.05999995888231524 3.64022064517418e-06
        rotation 1 6.604073036319333e-09 -6.551384359806268e-09 1.5707999857592654
        children [
          USE WHEELSIZE
        ]
        name "Wheel2"
        boundingObject USE WHEELSIZE
        physics USE WheelPhysics
      }
    }
    HingeJoint {
      jointParameters HingeJointParameters {
        axis 0 1 0
        anchor -0.05 -0.06 0
      }
      device [
        RotationalMotor {
          name "Wheel3"
        }
      ]
      endPoint Solid {
        translation -0.05 -0.06 0
        rotation 1 0 0 1.5707999835202933
        children [
          USE WHEELSIZE
        ]
        name "Wheel3"
        boundingObject USE WHEELSIZE
        physics USE WheelPhysics
      }
    }
    HingeJoint {
      jointParameters HingeJointParameters {
        axis 0 1 0
        anchor -0.05 0.06 0
      }
      device [
        RotationalMotor {
          name "Wheel4"
        }
      ]
      endPoint Solid {
        translation -0.049999996851340836 0.060000021341082885 4.130467837359915e-06
        rotation 1 -5.0653910242930504e-09 5.119238130299488e-09 1.5707999882284158
        children [
          USE WHEELSIZE
        ]
        name "Wheel4"
        boundingObject USE WHEELSIZE
        physics USE WheelPhysics
      }
    }
  ]
  name "Robot3"
  contactMaterial "white"
  boundingObject USE BODY
  physics Physics {
  }
  controller "drive_robot"
}
