#VRML_SIM R2023b utf8

EXTERNPROTO "https://raw.githubusercontent.com/cyberbotics/webots/R2023a/projects/objects/backgrounds/protos/TexturedBackground.proto"
EXTERNPROTO "https://raw.githubusercontent.com/cyberbotics/webots/R2023a/projects/objects/backgrounds/protos/TexturedBackgroundLight.proto"
EXTERNPROTO "https://raw.githubusercontent.com/cyberbotics/webots/R2023b/projects/objects/floors/protos/RectangleArena.proto"

WorldInfo {
  basicTimeStep 16
}
Viewpoint {
  orientation 0.5370398778003016 -0.5339310300397386 -0.6530741342397055 4.25662746596219
  position 6.583698980217438 -11.973409143699378 27.61852678555152
}
TexturedBackground {
  texture "morning_cloudy_empty"
}
TexturedBackgroundLight {
}
RectangleArena {
  translation 6 -4.5 0
  floorSize 13 10
  floorTileSize 2 2
  wallHeight 1.5
}
Robot {
  translation 12.01 -9.02 0.098806
  rotation 7.628487834490508e-08 -1.1493395721791664e-06 0.9999999999993368 1.570800000003245
  children [
    DistanceSensor {
    }
    DEF BODY Shape {
      appearance PBRAppearance {
        baseColor 0.666667 0 0
        metalness 0
      }
      geometry Box {
        size 0.4 0.2 0.1
      }
    }
    HingeJoint {
      jointParameters HingeJointParameters {
        position -3.758758255755347e-07
        axis 0 1 0
        anchor 0.1 0.12 0
      }
      device [
        RotationalMotor {
          name "Wheel1"
        }
      ]
      endPoint Solid {
        translation 0.1 0.12 0
        rotation 0.9999999999999647 -1.8790074833068118e-07 1.879014359628332e-07 1.5707999856069208
        children [
          DEF WHEELSIZE Shape {
            appearance PBRAppearance {
              baseColor 0 0 0
              metalness 0
            }
            geometry Cylinder {
              height 0.04
              radius 0.1
            }
          }
        ]
        name "Wheel1"
        boundingObject USE WHEELSIZE
        physics DEF WheelPhysics Physics {
          density -1
          mass 1
        }
      }
    }
    HingeJoint {
      jointParameters HingeJointParameters {
        position -6.684814028052229e-07
        axis 0 1 0
        anchor 0.1 -0.12 0
      }
      device [
        RotationalMotor {
          name "Wheel2"
        }
      ]
      endPoint Solid {
        translation 0.09999999999756642 -0.12 3.6402200000012706e-06
        rotation 0.9999999999998924 -3.276573378922375e-07 3.277112492656089e-07 1.5707999857593695
        children [
          USE WHEELSIZE
        ]
        name "Wheel2"
        boundingObject USE WHEELSIZE
        physics USE WheelPhysics
      }
    }
    HingeJoint {
      jointParameters HingeJointParameters {
        position -6.702059438080107e-07
        axis 0 1 0
        anchor -0.1 -0.12 0
      }
      device [
        RotationalMotor {
          name "Wheel3"
        }
      ]
      endPoint Solid {
        translation -0.1 -0.12 0
        rotation 0.9999999999998875 -3.3506529844963604e-07 3.350665230656247e-07 1.5707999835204052
        children [
          USE WHEELSIZE
        ]
        name "Wheel3"
        boundingObject USE WHEELSIZE
        physics USE WheelPhysics
      }
    }
    HingeJoint {
      jointParameters HingeJointParameters {
        position -3.7415394788342553e-07
        axis 0 1 0
        anchor -0.1 0.12 0
      }
      device [
        RotationalMotor {
          name "Wheel4"
        }
      ]
      endPoint Solid {
        translation -0.1000000000015456 0.12 4.130470000004354e-06
        rotation 0.9999999999999631 -1.9216363728903724e-07 1.9221816916878313e-07 1.57079998822845
        children [
          USE WHEELSIZE
        ]
        name "Wheel4"
        boundingObject USE WHEELSIZE
        physics USE WheelPhysics
      }
    }
  ]
  name "Robot15"
  boundingObject USE BODY
  physics Physics {
  }
  controller "drive_robot"
  customData "red,12,9"
}
Robot {
  translation 0.01 -7.97 0.088801
  rotation 7.628487834490508e-08 -1.1493395721791664e-06 0.9999999999993368 1.570800000003245
  children [
    DistanceSensor {
    }
    DEF BODY Shape {
      appearance PBRAppearance {
        baseColor 0.666667 0 0
        metalness 0
      }
      geometry Box {
        size 0.4 0.2 0.1
      }
    }
    HingeJoint {
      jointParameters HingeJointParameters {
        position -3.758758255755347e-07
        axis 0 1 0
        anchor 0.1 0.12 0
      }
      device [
        RotationalMotor {
          name "Wheel1"
        }
      ]
      endPoint Solid {
        translation 0.1 0.12 0
        rotation 0.9999999999999647 -1.8790074833068118e-07 1.879014359628332e-07 1.5707999856069208
        children [
          DEF WHEELSIZE Shape {
            appearance PBRAppearance {
              baseColor 0 0 0
              metalness 0
            }
            geometry Cylinder {
              height 0.04
              radius 0.1
            }
          }
        ]
        name "Wheel1"
        boundingObject USE WHEELSIZE
        physics DEF WheelPhysics Physics {
          density -1
          mass 1
        }
      }
    }
    HingeJoint {
      jointParameters HingeJointParameters {
        position -6.684814028052229e-07
        axis 0 1 0
        anchor 0.1 -0.12 0
      }
      device [
        RotationalMotor {
          name "Wheel2"
        }
      ]
      endPoint Solid {
        translation 0.09999999999756642 -0.12 3.6402200000012706e-06
        rotation 0.9999999999998924 -3.276573378922375e-07 3.277112492656089e-07 1.5707999857593695
        children [
          USE WHEELSIZE
        ]
        name "Wheel2"
        boundingObject USE WHEELSIZE
        physics USE WheelPhysics
      }
    }
    HingeJoint {
      jointParameters HingeJointParameters {
        position -6.702059438080107e-07
        axis 0 1 0
        anchor -0.1 -0.12 0
      }
      device [
        RotationalMotor {
          name "Wheel3"
        }
      ]
      endPoint Solid {
        translation -0.1 -0.12 0
        rotation 0.9999999999998875 -3.3506529844963604e-07 3.350665230656247e-07 1.5707999835204052
        children [
          USE WHEELSIZE
        ]
        name "Wheel3"
        boundingObject USE WHEELSIZE
        physics USE WheelPhysics
      }
    }
    HingeJoint {
      jointParameters HingeJointParameters {
        position -3.7415394788342553e-07
        axis 0 1 0
        anchor -0.1 0.12 0
      }
      device [
        RotationalMotor {
          name "Wheel4"
        }
      ]
      endPoint Solid {
        translation -0.1000000000015456 0.12 4.130470000004354e-06
        rotation 0.9999999999999631 -1.9216363728903724e-07 1.9221816916878313e-07 1.57079998822845
        children [
          USE WHEELSIZE
        ]
        name "Wheel4"
        boundingObject USE WHEELSIZE
        physics USE WheelPhysics
      }
    }
  ]
  name "Robot16"
  boundingObject USE BODY
  physics Physics {
  }
  controller "drive_robot"
  customData "red,0,8"
}
Robot {
  translation 1.03 -7.97 0.098801
  rotation 7.628487834490508e-08 -1.1493395721791664e-06 0.9999999999993368 1.570800000003245
  children [
    DistanceSensor {
    }
    DEF BODY Shape {
      appearance PBRAppearance {
        baseColor 0.666667 0 0
        metalness 0
      }
      geometry Box {
        size 0.4 0.2 0.1
      }
    }
    HingeJoint {
      jointParameters HingeJointParameters {
        position -3.758758255755347e-07
        axis 0 1 0
        anchor 0.1 0.12 0
      }
      device [
        RotationalMotor {
          name "Wheel1"
        }
      ]
      endPoint Solid {
        translation 0.1 0.12 0
        rotation 0.9999999999999647 -1.8790074833068118e-07 1.879014359628332e-07 1.5707999856069208
        children [
          DEF WHEELSIZE Shape {
            appearance PBRAppearance {
              baseColor 0 0 0
              metalness 0
            }
            geometry Cylinder {
              height 0.04
              radius 0.1
            }
          }
        ]
        name "Wheel1"
        boundingObject USE WHEELSIZE
        physics DEF WheelPhysics Physics {
          density -1
          mass 1
        }
      }
    }
    HingeJoint {
      jointParameters HingeJointParameters {
        position -6.684814028052229e-07
        axis 0 1 0
        anchor 0.1 -0.12 0
      }
      device [
        RotationalMotor {
          name "Wheel2"
        }
      ]
      endPoint Solid {
        translation 0.09999999999756642 -0.12 3.6402200000012706e-06
        rotation 0.9999999999998924 -3.276573378922375e-07 3.277112492656089e-07 1.5707999857593695
        children [
          USE WHEELSIZE
        ]
        name "Wheel2"
        boundingObject USE WHEELSIZE
        physics USE WheelPhysics
      }
    }
    HingeJoint {
      jointParameters HingeJointParameters {
        position -6.702059438080107e-07
        axis 0 1 0
        anchor -0.1 -0.12 0
      }
      device [
        RotationalMotor {
          name "Wheel3"
        }
      ]
      endPoint Solid {
        translation -0.1 -0.12 0
        rotation 0.9999999999998875 -3.3506529844963604e-07 3.350665230656247e-07 1.5707999835204052
        children [
          USE WHEELSIZE
        ]
        name "Wheel3"
        boundingObject USE WHEELSIZE
        physics USE WheelPhysics
      }
    }
    HingeJoint {
      jointParameters HingeJointParameters {
        position -3.7415394788342553e-07
        axis 0 1 0
        anchor -0.1 0.12 0
      }
      device [
        RotationalMotor {
          name "Wheel4"
        }
      ]
      endPoint Solid {
        translation -0.1000000000015456 0.12 4.130470000004354e-06
        rotation 0.9999999999999631 -1.9216363728903724e-07 1.9221816916878313e-07 1.57079998822845
        children [
          USE WHEELSIZE
        ]
        name "Wheel4"
        boundingObject USE WHEELSIZE
        physics USE WheelPhysics
      }
    }
  ]
  name "Robot17"
  boundingObject USE BODY
  physics Physics {
  }
  controller "drive_robot"
  customData "red,1,8"
}
Robot {
  translation 2.05 -7.97 0.108801
  rotation 7.628487834490508e-08 -1.1493395721791664e-06 0.9999999999993368 1.570800000003245
  children [
    DistanceSensor {
    }
    DEF BODY Shape {
      appearance PBRAppearance {
        baseColor 0.666667 0 0
        metalness 0
      }
      geometry Box {
        size 0.4 0.2 0.1
      }
    }
    HingeJoint {
      jointParameters HingeJointParameters {
        position -3.758758255755347e-07
        axis 0 1 0
        anchor 0.1 0.12 0
      }
      device [
        RotationalMotor {
          name "Wheel1"
        }
      ]
      endPoint Solid {
        translation 0.1 0.12 0
        rotation 0.9999999999999647 -1.8790074833068118e-07 1.879014359628332e-07 1.5707999856069208
        children [
          DEF WHEELSIZE Shape {
            appearance PBRAppearance {
              baseColor 0 0 0
              metalness 0
            }
            geometry Cylinder {
              height 0.04
              radius 0.1
            }
          }
        ]
        name "Wheel1"
        boundingObject USE WHEELSIZE
        physics DEF WheelPhysics Physics {
          density -1
          mass 1
        }
      }
    }
    HingeJoint {
      jointParameters HingeJointParameters {
        position -6.684814028052229e-07
        axis 0 1 0
        anchor 0.1 -0.12 0
      }
      device [
        RotationalMotor {
          name "Wheel2"
        }
      ]
      endPoint Solid {
        translation 0.09999999999756642 -0.12 3.6402200000012706e-06
        rotation 0.9999999999998924 -3.276573378922375e-07 3.277112492656089e-07 1.5707999857593695
        children [
          USE WHEELSIZE
        ]
        name "Wheel2"
        boundingObject USE WHEELSIZE
        physics USE WheelPhysics
      }
    }
    HingeJoint {
      jointParameters HingeJointParameters {
        position -6.702059438080107e-07
        axis 0 1 0
        anchor -0.1 -0.12 0
      }
      device [
        RotationalMotor {
          name "Wheel3"
        }
      ]
      endPoint Solid {
        translation -0.1 -0.12 0
        rotation 0.9999999999998875 -3.3506529844963604e-07 3.350665230656247e-07 1.5707999835204052
        children [
          USE WHEELSIZE
        ]
        name "Wheel3"
        boundingObject USE WHEELSIZE
        physics USE WheelPhysics
      }
    }
    HingeJoint {
      jointParameters HingeJointParameters {
        position -3.7415394788342553e-07
        axis 0 1 0
        anchor -0.1 0.12 0
      }
      device [
        RotationalMotor {
          name "Wheel4"
        }
      ]
      endPoint Solid {
        translation -0.1000000000015456 0.12 4.130470000004354e-06
        rotation 0.9999999999999631 -1.9216363728903724e-07 1.9221816916878313e-07 1.57079998822845
        children [
          USE WHEELSIZE
        ]
        name "Wheel4"
        boundingObject USE WHEELSIZE
        physics USE WheelPhysics
      }
    }
  ]
  name "Robot18"
  boundingObject USE BODY
  physics Physics {
  }
  controller "drive_robot"
  customData "red,2,8"
}
Robot {
  translation 2.940030000282603 -9.020000000000035 0.09880516132716563
  rotation 7.628491826564971e-08 -1.149339611637448e-06 0.9999999999993368 1.5708000000005347
  children [
    DistanceSensor {
    }
    DEF BODY Shape {
      appearance PBRAppearance {
        baseColor 0.666667 0 0
        metalness 0
      }
      geometry Box {
        size 0.4 0.2 0.1
      }
    }
    HingeJoint {
      jointParameters HingeJointParameters {
        position 2.917926097885631e-11
        axis 0 1 0
        anchor 0.1 0.12 0
      }
      device [
        RotationalMotor {
          name "Wheel1"
        }
      ]
      endPoint Solid {
        translation 0.1 0.12 0
        rotation 1 3.136791804608803e-10 -3.1368019077271435e-10 1.5707999856068906
        children [
          DEF WHEELSIZE Shape {
            appearance PBRAppearance {
              baseColor 0 0 0
              metalness 0
            }
            geometry Cylinder {
              height 0.04
              radius 0.1
            }
          }
        ]
        name "Wheel1"
        boundingObject USE WHEELSIZE
        physics DEF WheelPhysics Physics {
          density -1
          mass 1
        }
      }
    }
    HingeJoint {
      jointParameters HingeJointParameters {
        position -9.724587776652118e-15
        axis 0 1 0
        anchor 0.1 -0.12 0
      }
      device [
        RotationalMotor {
          name "Wheel2"
        }
      ]
      endPoint Solid {
        translation 0.09999999999999984 -0.12 3.6402200000020727e-06
        rotation 1 6.582072096127841e-09 -6.529383695085761e-09 1.5707999857592636
        children [
          USE WHEELSIZE
        ]
        name "Wheel2"
        boundingObject USE WHEELSIZE
        physics USE WheelPhysics
      }
    }
    HingeJoint {
      jointParameters HingeJointParameters {
        position 2.9156745642340747e-11
        axis 0 1 0
        anchor -0.1 -0.12 0
      }
      device [
        RotationalMotor {
          name "Wheel3"
        }
      ]
      endPoint Solid {
        translation -0.1 -0.12 0
        rotation 1 3.134366992777655e-10 -3.1343847346964435e-10 1.570799983520293
        children [
          USE WHEELSIZE
        ]
        name "Wheel3"
        boundingObject USE WHEELSIZE
        physics USE WheelPhysics
      }
    }
    HingeJoint {
      jointParameters HingeJointParameters {
        position -1.2293132562136235e-14
        axis 0 1 0
        anchor -0.1 0.12 0
      }
      device [
        RotationalMotor {
          name "Wheel4"
        }
      ]
      endPoint Solid {
        translation -0.10000000000000017 0.12 4.130470000004657e-06
        rotation 1 -5.087435231815838e-09 5.1412821432314095e-09 1.5707999882284138
        children [
          USE WHEELSIZE
        ]
        name "Wheel4"
        boundingObject USE WHEELSIZE
        physics USE WheelPhysics
      }
    }
  ]
  name "Robot6"
  boundingObject USE BODY
  physics Physics {
  }
  controller "drive_robot"
  customData "red,3,9"
}
Robot {
  translation 3.34779e-05 -9.02 0.0988052
  rotation 7.628476053430804e-08 -1.149339785963148e-06 0.9999999999993366 1.5707997131026343
  children [
    DistanceSensor {
    }
    DEF BODY Shape {
      appearance PBRAppearance {
        baseColor 0 1 0
        metalness 0
      }
      geometry Box {
        size 0.4 0.2 0.1
      }
    }
    HingeJoint {
      jointParameters HingeJointParameters {
        position 3.8298616043356944e-08
        axis 0 1 0
        anchor 0.1 0.12 0
      }
      device [
        RotationalMotor {
          name "Wheel1"
        }
      ]
      endPoint Solid {
        translation 0.1 0.12 0
        rotation 0.9999999999999996 1.914923811509773e-08 -1.9149308041304586e-08 1.5707999856068906
        children [
          DEF WHEELSIZE Shape {
            appearance PBRAppearance {
              baseColor 0 0 0
              metalness 0
            }
            geometry Cylinder {
              height 0.04
              radius 0.1
            }
          }
        ]
        name "Wheel1"
        boundingObject USE WHEELSIZE
        physics DEF WheelPhysics Physics {
          density -1
          mass 1
        }
      }
    }
    HingeJoint {
      jointParameters HingeJointParameters {
        position -3.176474550059538e-08
        axis 0 1 0
        anchor 0.1 -0.12 0
      }
      device [
        RotationalMotor {
          name "Wheel2"
        }
      ]
      endPoint Solid {
        translation 0.09999999999988438 -0.12 3.640220000002077e-06
        rotation 1 -9.27824189441685e-09 9.330988327888827e-09 1.5707999857592636
        children [
          USE WHEELSIZE
        ]
        name "Wheel2"
        boundingObject USE WHEELSIZE
        physics USE WheelPhysics
      }
    }
    HingeJoint {
      jointParameters HingeJointParameters {
        position 2.9143387833612897e-08
        axis 0 1 0
        anchor -0.1 -0.12 0
      }
      device [
        RotationalMotor {
          name "Wheel3"
        }
      ]
      endPoint Solid {
        translation -0.1 -0.12 0
        rotation 0.9999999999999997 1.4571640082689296e-08 -1.4571693995310926e-08 1.5707999835202937
        children [
          USE WHEELSIZE
        ]
        name "Wheel3"
        boundingObject USE WHEELSIZE
        physics USE WheelPhysics
      }
    }
    HingeJoint {
      jointParameters HingeJointParameters {
        position -3.566959438927597e-08
        axis 0 1 0
        anchor -0.1 0.12 0
      }
      device [
        RotationalMotor {
          name "Wheel4"
        }
      ]
      endPoint Solid {
        translation -0.10000000000014733 0.12 4.130470000004679e-06
        rotation 0.9999999999999996 -2.2900123234135275e-08 2.2954035365643086e-08 1.5707999882284098
        children [
          USE WHEELSIZE
        ]
        name "Wheel4"
        boundingObject USE WHEELSIZE
        physics USE WheelPhysics
      }
    }
  ]
  name "Robot3"
  boundingObject USE BODY
  physics Physics {
  }
  controller "drive_robot"
  customData "green,0,9"
}
Robot {
  translation 1.00003 -9.02 0.0988052
  rotation 7.628491710494937e-08 -1.1493396128274498e-06 0.9999999999993368 1.5708000000005298
  children [
    DistanceSensor {
    }
    DEF BODY Shape {
      appearance PBRAppearance {
        baseColor 0 1 0
        metalness 0
      }
      geometry Box {
        size 0.4 0.2 0.1
      }
    }
    HingeJoint {
      jointParameters HingeJointParameters {
        position 1.4596357779530014e-11
        axis 0 1 0
        anchor 0.1 0.12 0
      }
      device [
        RotationalMotor {
          name "Wheel1"
        }
      ]
      endPoint Solid {
        translation 0.1 0.12 0
        rotation 1 1.4596320075194674e-10 -1.4596359742142004e-10 1.5707999856068906
        children [
          DEF WHEELSIZE Shape {
            appearance PBRAppearance {
              baseColor 0 0 0
              metalness 0
            }
            geometry Cylinder {
              height 0.04
              radius 0.1
            }
          }
        ]
        name "Wheel1"
        boundingObject USE WHEELSIZE
        physics DEF WheelPhysics Physics {
          density -1
          mass 1
        }
      }
    }
    HingeJoint {
      jointParameters HingeJointParameters {
        position -1.461586407458526e-11
        axis 0 1 0
        anchor 0.1 -0.12 0
      }
      device [
        RotationalMotor {
          name "Wheel2"
        }
      ]
      endPoint Solid {
        translation 0.0999999999999989 -0.12 3.6402200000020727e-06
        rotation 1 6.457914636993619e-09 -6.405225781663003e-09 1.5707999857592636
        children [
          USE WHEELSIZE
        ]
        name "Wheel2"
        boundingObject USE WHEELSIZE
        physics USE WheelPhysics
      }
    }
    HingeJoint {
      jointParameters HingeJointParameters {
        position 1.4584619329972877e-11
        axis 0 1 0
        anchor -0.1 -0.12 0
      }
      device [
        RotationalMotor {
          name "Wheel3"
        }
      ]
      endPoint Solid {
        translation -0.1 -0.12 0
        rotation 1 1.458451104498689e-10 -1.4584627180420817e-10 1.570799983520293
        children [
          USE WHEELSIZE
        ]
        name "Wheel3"
        boundingObject USE WHEELSIZE
        physics USE WheelPhysics
      }
    }
    HingeJoint {
      jointParameters HingeJointParameters {
        position -1.4630963107720163e-11
        axis 0 1 0
        anchor -0.1 0.12 0
      }
      device [
        RotationalMotor {
          name "Wheel4"
        }
      ]
      endPoint Solid {
        translation -0.10000000000000112 0.12 4.130470000004657e-06
        rotation 1 -5.211700435677111e-09 5.2655478020822986e-09 1.5707999882284138
        children [
          USE WHEELSIZE
        ]
        name "Wheel4"
        boundingObject USE WHEELSIZE
        physics USE WheelPhysics
      }
    }
  ]
  name "Robot4"
  boundingObject USE BODY
  physics Physics {
  }
  controller "drive_robot"
  customData "green,1,9"
}
Robot {
  translation 2.0500292111085137 -9.020000000036767 0.09880516132716566
  rotation 7.628487834490508e-08 -1.1493395721791664e-06 0.9999999999993368 1.570800000003245
  children [
    DistanceSensor {
    }
    DEF BODY Shape {
      appearance PBRAppearance {
        baseColor 0.666667 0 0
        metalness 0
      }
      geometry Box {
        size 0.4 0.2 0.1
      }
    }
    HingeJoint {
      jointParameters HingeJointParameters {
        position -3.758758255755347e-07
        axis 0 1 0
        anchor 0.1 0.12 0
      }
      device [
        RotationalMotor {
          name "Wheel1"
        }
      ]
      endPoint Solid {
        translation 0.1 0.12 0
        rotation 0.9999999999999647 -1.8790074833068118e-07 1.879014359628332e-07 1.5707999856069208
        children [
          DEF WHEELSIZE Shape {
            appearance PBRAppearance {
              baseColor 0 0 0
              metalness 0
            }
            geometry Cylinder {
              height 0.04
              radius 0.1
            }
          }
        ]
        name "Wheel1"
        boundingObject USE WHEELSIZE
        physics DEF WheelPhysics Physics {
          density -1
          mass 1
        }
      }
    }
    HingeJoint {
      jointParameters HingeJointParameters {
        position -6.684814028052229e-07
        axis 0 1 0
        anchor 0.1 -0.12 0
      }
      device [
        RotationalMotor {
          name "Wheel2"
        }
      ]
      endPoint Solid {
        translation 0.09999999999756642 -0.12 3.6402200000012706e-06
        rotation 0.9999999999998924 -3.276573378922375e-07 3.277112492656089e-07 1.5707999857593695
        children [
          USE WHEELSIZE
        ]
        name "Wheel2"
        boundingObject USE WHEELSIZE
        physics USE WheelPhysics
      }
    }
    HingeJoint {
      jointParameters HingeJointParameters {
        position -6.702059438080107e-07
        axis 0 1 0
        anchor -0.1 -0.12 0
      }
      device [
        RotationalMotor {
          name "Wheel3"
        }
      ]
      endPoint Solid {
        translation -0.1 -0.12 0
        rotation 0.9999999999998875 -3.3506529844963604e-07 3.350665230656247e-07 1.5707999835204052
        children [
          USE WHEELSIZE
        ]
        name "Wheel3"
        boundingObject USE WHEELSIZE
        physics USE WheelPhysics
      }
    }
    HingeJoint {
      jointParameters HingeJointParameters {
        position -3.7415394788342553e-07
        axis 0 1 0
        anchor -0.1 0.12 0
      }
      device [
        RotationalMotor {
          name "Wheel4"
        }
      ]
      endPoint Solid {
        translation -0.1000000000015456 0.12 4.130470000004354e-06
        rotation 0.9999999999999631 -1.9216363728903724e-07 1.9221816916878313e-07 1.57079998822845
        children [
          USE WHEELSIZE
        ]
        name "Wheel4"
        boundingObject USE WHEELSIZE
        physics USE WheelPhysics
      }
    }
  ]
  name "Robot5"
  boundingObject USE BODY
  physics Physics {
  }
  controller "drive_robot"
  customData "red,2,9"
}
Robot {
  translation 3.96003 -9.02 0.098805
  rotation 7.628487834490508e-08 -1.1493395721791664e-06 0.9999999999993368 1.570800000003245
  children [
    DistanceSensor {
    }
    DEF BODY Shape {
      appearance PBRAppearance {
        baseColor 0 0.333333 1
        metalness 0
      }
      geometry Box {
        size 0.4 0.2 0.1
      }
    }
    HingeJoint {
      jointParameters HingeJointParameters {
        position -3.758758255755347e-07
        axis 0 1 0
        anchor 0.1 0.12 0
      }
      device [
        RotationalMotor {
          name "Wheel1"
        }
      ]
      endPoint Solid {
        translation 0.1 0.12 0
        rotation 0.9999999999999647 -1.8790074833068118e-07 1.879014359628332e-07 1.5707999856069208
        children [
          DEF WHEELSIZE Shape {
            appearance PBRAppearance {
              baseColor 0 0 0
              metalness 0
            }
            geometry Cylinder {
              height 0.04
              radius 0.1
            }
          }
        ]
        name "Wheel1"
        boundingObject USE WHEELSIZE
        physics DEF WheelPhysics Physics {
          density -1
          mass 1
        }
      }
    }
    HingeJoint {
      jointParameters HingeJointParameters {
        position -6.684814028052229e-07
        axis 0 1 0
        anchor 0.1 -0.12 0
      }
      device [
        RotationalMotor {
          name "Wheel2"
        }
      ]
      endPoint Solid {
        translation 0.09999999999756642 -0.12 3.6402200000012706e-06
        rotation 0.9999999999998924 -3.276573378922375e-07 3.277112492656089e-07 1.5707999857593695
        children [
          USE WHEELSIZE
        ]
        name "Wheel2"
        boundingObject USE WHEELSIZE
        physics USE WheelPhysics
      }
    }
    HingeJoint {
      jointParameters HingeJointParameters {
        position -6.702059438080107e-07
        axis 0 1 0
        anchor -0.1 -0.12 0
      }
      device [
        RotationalMotor {
          name "Wheel3"
        }
      ]
      endPoint Solid {
        translation -0.1 -0.12 0
        rotation 0.9999999999998875 -3.3506529844963604e-07 3.350665230656247e-07 1.5707999835204052
        children [
          USE WHEELSIZE
        ]
        name "Wheel3"
        boundingObject USE WHEELSIZE
        physics USE WheelPhysics
      }
    }
    HingeJoint {
      jointParameters HingeJointParameters {
        position -3.7415394788342553e-07
        axis 0 1 0
        anchor -0.1 0.12 0
      }
      device [
        RotationalMotor {
          name "Wheel4"
        }
      ]
      endPoint Solid {
        translation -0.1000000000015456 0.12 4.130470000004354e-06
        rotation 0.9999999999999631 -1.9216363728903724e-07 1.9221816916878313e-07 1.57079998822845
        children [
          USE WHEELSIZE
        ]
        name "Wheel4"
        boundingObject USE WHEELSIZE
        physics USE WheelPhysics
      }
    }
  ]
  name "Robot7"
  boundingObject USE BODY
  physics Physics {
  }
  controller "drive_robot"
  customData "blue,4,9"
}
Robot {
  translation 4.99003 -9.02 0.108805
  rotation 7.628487834490508e-08 -1.1493395721791664e-06 0.9999999999993368 1.570800000003245
  children [
    DistanceSensor {
    }
    DEF BODY Shape {
      appearance PBRAppearance {
        baseColor 0 0.333333 1
        metalness 0
      }
      geometry Box {
        size 0.4 0.2 0.1
      }
    }
    HingeJoint {
      jointParameters HingeJointParameters {
        position -3.758758255755347e-07
        axis 0 1 0
        anchor 0.1 0.12 0
      }
      device [
        RotationalMotor {
          name "Wheel1"
        }
      ]
      endPoint Solid {
        translation 0.1 0.12 0
        rotation 0.9999999999999647 -1.8790074833068118e-07 1.879014359628332e-07 1.5707999856069208
        children [
          DEF WHEELSIZE Shape {
            appearance PBRAppearance {
              baseColor 0 0 0
              metalness 0
            }
            geometry Cylinder {
              height 0.04
              radius 0.1
            }
          }
        ]
        name "Wheel1"
        boundingObject USE WHEELSIZE
        physics DEF WheelPhysics Physics {
          density -1
          mass 1
        }
      }
    }
    HingeJoint {
      jointParameters HingeJointParameters {
        position -6.684814028052229e-07
        axis 0 1 0
        anchor 0.1 -0.12 0
      }
      device [
        RotationalMotor {
          name "Wheel2"
        }
      ]
      endPoint Solid {
        translation 0.09999999999756642 -0.12 3.6402200000012706e-06
        rotation 0.9999999999998924 -3.276573378922375e-07 3.277112492656089e-07 1.5707999857593695
        children [
          USE WHEELSIZE
        ]
        name "Wheel2"
        boundingObject USE WHEELSIZE
        physics USE WheelPhysics
      }
    }
    HingeJoint {
      jointParameters HingeJointParameters {
        position -6.702059438080107e-07
        axis 0 1 0
        anchor -0.1 -0.12 0
      }
      device [
        RotationalMotor {
          name "Wheel3"
        }
      ]
      endPoint Solid {
        translation -0.1 -0.12 0
        rotation 0.9999999999998875 -3.3506529844963604e-07 3.350665230656247e-07 1.5707999835204052
        children [
          USE WHEELSIZE
        ]
        name "Wheel3"
        boundingObject USE WHEELSIZE
        physics USE WheelPhysics
      }
    }
    HingeJoint {
      jointParameters HingeJointParameters {
        position -3.7415394788342553e-07
        axis 0 1 0
        anchor -0.1 0.12 0
      }
      device [
        RotationalMotor {
          name "Wheel4"
        }
      ]
      endPoint Solid {
        translation -0.1000000000015456 0.12 4.130470000004354e-06
        rotation 0.9999999999999631 -1.9216363728903724e-07 1.9221816916878313e-07 1.57079998822845
        children [
          USE WHEELSIZE
        ]
        name "Wheel4"
        boundingObject USE WHEELSIZE
        physics USE WheelPhysics
      }
    }
  ]
  name "Robot8"
  boundingObject USE BODY
  physics Physics {
  }
  controller "drive_robot"
  customData "blue,5,9"
}
Robot {
  translation 5.98003 -9.02 0.108806
  rotation 7.628487834490508e-08 -1.1493395721791664e-06 0.9999999999993368 1.570800000003245
  children [
    DistanceSensor {
    }
    DEF BODY Shape {
      appearance PBRAppearance {
        baseColor 0 0.333333 1
        metalness 0
      }
      geometry Box {
        size 0.4 0.2 0.1
      }
    }
    HingeJoint {
      jointParameters HingeJointParameters {
        position -3.758758255755347e-07
        axis 0 1 0
        anchor 0.1 0.12 0
      }
      device [
        RotationalMotor {
          name "Wheel1"
        }
      ]
      endPoint Solid {
        translation 0.1 0.12 0
        rotation 0.9999999999999647 -1.8790074833068118e-07 1.879014359628332e-07 1.5707999856069208
        children [
          DEF WHEELSIZE Shape {
            appearance PBRAppearance {
              baseColor 0 0 0
              metalness 0
            }
            geometry Cylinder {
              height 0.04
              radius 0.1
            }
          }
        ]
        name "Wheel1"
        boundingObject USE WHEELSIZE
        physics DEF WheelPhysics Physics {
          density -1
          mass 1
        }
      }
    }
    HingeJoint {
      jointParameters HingeJointParameters {
        position -6.684814028052229e-07
        axis 0 1 0
        anchor 0.1 -0.12 0
      }
      device [
        RotationalMotor {
          name "Wheel2"
        }
      ]
      endPoint Solid {
        translation 0.09999999999756642 -0.12 3.6402200000012706e-06
        rotation 0.9999999999998924 -3.276573378922375e-07 3.277112492656089e-07 1.5707999857593695
        children [
          USE WHEELSIZE
        ]
        name "Wheel2"
        boundingObject USE WHEELSIZE
        physics USE WheelPhysics
      }
    }
    HingeJoint {
      jointParameters HingeJointParameters {
        position -6.702059438080107e-07
        axis 0 1 0
        anchor -0.1 -0.12 0
      }
      device [
        RotationalMotor {
          name "Wheel3"
        }
      ]
      endPoint Solid {
        translation -0.1 -0.12 0
        rotation 0.9999999999998875 -3.3506529844963604e-07 3.350665230656247e-07 1.5707999835204052
        children [
          USE WHEELSIZE
        ]
        name "Wheel3"
        boundingObject USE WHEELSIZE
        physics USE WheelPhysics
      }
    }
    HingeJoint {
      jointParameters HingeJointParameters {
        position -3.7415394788342553e-07
        axis 0 1 0
        anchor -0.1 0.12 0
      }
      device [
        RotationalMotor {
          name "Wheel4"
        }
      ]
      endPoint Solid {
        translation -0.1000000000015456 0.12 4.130470000004354e-06
        rotation 0.9999999999999631 -1.9216363728903724e-07 1.9221816916878313e-07 1.57079998822845
        children [
          USE WHEELSIZE
        ]
        name "Wheel4"
        boundingObject USE WHEELSIZE
        physics USE WheelPhysics
      }
    }
  ]
  name "Robot9"
  boundingObject USE BODY
  physics Physics {
  }
  controller "drive_robot"
  customData "blue,6,9"
}
Robot {
  translation 7.07003 -9.02 0.098806
  rotation 7.628487834490508e-08 -1.1493395721791664e-06 0.9999999999993368 1.570800000003245
  children [
    DistanceSensor {
    }
    DEF BODY Shape {
      appearance PBRAppearance {
        baseColor 0 0.333333 1
        metalness 0
      }
      geometry Box {
        size 0.4 0.2 0.1
      }
    }
    HingeJoint {
      jointParameters HingeJointParameters {
        position -3.758758255755347e-07
        axis 0 1 0
        anchor 0.1 0.12 0
      }
      device [
        RotationalMotor {
          name "Wheel1"
        }
      ]
      endPoint Solid {
        translation 0.1 0.12 0
        rotation 0.9999999999999647 -1.8790074833068118e-07 1.879014359628332e-07 1.5707999856069208
        children [
          DEF WHEELSIZE Shape {
            appearance PBRAppearance {
              baseColor 0 0 0
              metalness 0
            }
            geometry Cylinder {
              height 0.04
              radius 0.1
            }
          }
        ]
        name "Wheel1"
        boundingObject USE WHEELSIZE
        physics DEF WheelPhysics Physics {
          density -1
          mass 1
        }
      }
    }
    HingeJoint {
      jointParameters HingeJointParameters {
        position -6.684814028052229e-07
        axis 0 1 0
        anchor 0.1 -0.12 0
      }
      device [
        RotationalMotor {
          name "Wheel2"
        }
      ]
      endPoint Solid {
        translation 0.09999999999756642 -0.12 3.6402200000012706e-06
        rotation 0.9999999999998924 -3.276573378922375e-07 3.277112492656089e-07 1.5707999857593695
        children [
          USE WHEELSIZE
        ]
        name "Wheel2"
        boundingObject USE WHEELSIZE
        physics USE WheelPhysics
      }
    }
    HingeJoint {
      jointParameters HingeJointParameters {
        position -6.702059438080107e-07
        axis 0 1 0
        anchor -0.1 -0.12 0
      }
      device [
        RotationalMotor {
          name "Wheel3"
        }
      ]
      endPoint Solid {
        translation -0.1 -0.12 0
        rotation 0.9999999999998875 -3.3506529844963604e-07 3.350665230656247e-07 1.5707999835204052
        children [
          USE WHEELSIZE
        ]
        name "Wheel3"
        boundingObject USE WHEELSIZE
        physics USE WheelPhysics
      }
    }
    HingeJoint {
      jointParameters HingeJointParameters {
        position -3.7415394788342553e-07
        axis 0 1 0
        anchor -0.1 0.12 0
      }
      device [
        RotationalMotor {
          name "Wheel4"
        }
      ]
      endPoint Solid {
        translation -0.1000000000015456 0.12 4.130470000004354e-06
        rotation 0.9999999999999631 -1.9216363728903724e-07 1.9221816916878313e-07 1.57079998822845
        children [
          USE WHEELSIZE
        ]
        name "Wheel4"
        boundingObject USE WHEELSIZE
        physics USE WheelPhysics
      }
    }
  ]
  name "Robot10"
  boundingObject USE BODY
  physics Physics {
  }
  controller "drive_robot"
  customData "blue,7,9"
}
Robot {
  translation 7.96003 -9.02 0.098806
  rotation 7.628487834490508e-08 -1.1493395721791664e-06 0.9999999999993368 1.570800000003245
  children [
    DistanceSensor {
    }
    DEF BODY Shape {
      appearance PBRAppearance {
        baseColor 0 0.333333 1
        metalness 0
      }
      geometry Box {
        size 0.4 0.2 0.1
      }
    }
    HingeJoint {
      jointParameters HingeJointParameters {
        position -3.758758255755347e-07
        axis 0 1 0
        anchor 0.1 0.12 0
      }
      device [
        RotationalMotor {
          name "Wheel1"
        }
      ]
      endPoint Solid {
        translation 0.1 0.12 0
        rotation 0.9999999999999647 -1.8790074833068118e-07 1.879014359628332e-07 1.5707999856069208
        children [
          DEF WHEELSIZE Shape {
            appearance PBRAppearance {
              baseColor 0 0 0
              metalness 0
            }
            geometry Cylinder {
              height 0.04
              radius 0.1
            }
          }
        ]
        name "Wheel1"
        boundingObject USE WHEELSIZE
        physics DEF WheelPhysics Physics {
          density -1
          mass 1
        }
      }
    }
    HingeJoint {
      jointParameters HingeJointParameters {
        position -6.684814028052229e-07
        axis 0 1 0
        anchor 0.1 -0.12 0
      }
      device [
        RotationalMotor {
          name "Wheel2"
        }
      ]
      endPoint Solid {
        translation 0.09999999999756642 -0.12 3.6402200000012706e-06
        rotation 0.9999999999998924 -3.276573378922375e-07 3.277112492656089e-07 1.5707999857593695
        children [
          USE WHEELSIZE
        ]
        name "Wheel2"
        boundingObject USE WHEELSIZE
        physics USE WheelPhysics
      }
    }
    HingeJoint {
      jointParameters HingeJointParameters {
        position -6.702059438080107e-07
        axis 0 1 0
        anchor -0.1 -0.12 0
      }
      device [
        RotationalMotor {
          name "Wheel3"
        }
      ]
      endPoint Solid {
        translation -0.1 -0.12 0
        rotation 0.9999999999998875 -3.3506529844963604e-07 3.350665230656247e-07 1.5707999835204052
        children [
          USE WHEELSIZE
        ]
        name "Wheel3"
        boundingObject USE WHEELSIZE
        physics USE WheelPhysics
      }
    }
    HingeJoint {
      jointParameters HingeJointParameters {
        position -3.7415394788342553e-07
        axis 0 1 0
        anchor -0.1 0.12 0
      }
      device [
        RotationalMotor {
          name "Wheel4"
        }
      ]
      endPoint Solid {
        translation -0.1000000000015456 0.12 4.130470000004354e-06
        rotation 0.9999999999999631 -1.9216363728903724e-07 1.9221816916878313e-07 1.57079998822845
        children [
          USE WHEELSIZE
        ]
        name "Wheel4"
        boundingObject USE WHEELSIZE
        physics USE WheelPhysics
      }
    }
  ]
  name "Robot11"
  boundingObject USE BODY
  physics Physics {
  }
  controller "drive_robot"
  customData "blue,8,9"
}
Robot {
  translation 8.96003 -9.02 0.098806
  rotation 7.628487834490508e-08 -1.1493395721791664e-06 0.9999999999993368 1.570800000003245
  children [
    DistanceSensor {
    }
    DEF BODY Shape {
      appearance PBRAppearance {
        baseColor 0 0.666667 0
        metalness 0
      }
      geometry Box {
        size 0.4 0.2 0.1
      }
    }
    HingeJoint {
      jointParameters HingeJointParameters {
        position -3.758758255755347e-07
        axis 0 1 0
        anchor 0.1 0.12 0
      }
      device [
        RotationalMotor {
          name "Wheel1"
        }
      ]
      endPoint Solid {
        translation 0.1 0.12 0
        rotation 0.9999999999999647 -1.8790074833068118e-07 1.879014359628332e-07 1.5707999856069208
        children [
          DEF WHEELSIZE Shape {
            appearance PBRAppearance {
              baseColor 0 0 0
              metalness 0
            }
            geometry Cylinder {
              height 0.04
              radius 0.1
            }
          }
        ]
        name "Wheel1"
        boundingObject USE WHEELSIZE
        physics DEF WheelPhysics Physics {
          density -1
          mass 1
        }
      }
    }
    HingeJoint {
      jointParameters HingeJointParameters {
        position -6.684814028052229e-07
        axis 0 1 0
        anchor 0.1 -0.12 0
      }
      device [
        RotationalMotor {
          name "Wheel2"
        }
      ]
      endPoint Solid {
        translation 0.09999999999756642 -0.12 3.6402200000012706e-06
        rotation 0.9999999999998924 -3.276573378922375e-07 3.277112492656089e-07 1.5707999857593695
        children [
          USE WHEELSIZE
        ]
        name "Wheel2"
        boundingObject USE WHEELSIZE
        physics USE WheelPhysics
      }
    }
    HingeJoint {
      jointParameters HingeJointParameters {
        position -6.702059438080107e-07
        axis 0 1 0
        anchor -0.1 -0.12 0
      }
      device [
        RotationalMotor {
          name "Wheel3"
        }
      ]
      endPoint Solid {
        translation -0.1 -0.12 0
        rotation 0.9999999999998875 -3.3506529844963604e-07 3.350665230656247e-07 1.5707999835204052
        children [
          USE WHEELSIZE
        ]
        name "Wheel3"
        boundingObject USE WHEELSIZE
        physics USE WheelPhysics
      }
    }
    HingeJoint {
      jointParameters HingeJointParameters {
        position -3.7415394788342553e-07
        axis 0 1 0
        anchor -0.1 0.12 0
      }
      device [
        RotationalMotor {
          name "Wheel4"
        }
      ]
      endPoint Solid {
        translation -0.1000000000015456 0.12 4.130470000004354e-06
        rotation 0.9999999999999631 -1.9216363728903724e-07 1.9221816916878313e-07 1.57079998822845
        children [
          USE WHEELSIZE
        ]
        name "Wheel4"
        boundingObject USE WHEELSIZE
        physics USE WheelPhysics
      }
    }
  ]
  name "Robot12"
  boundingObject USE BODY
  physics Physics {
  }
  controller "drive_robot"
  customData "green,9,9"
}
Robot {
  translation 9.99 -9.02 0.088806
  rotation 7.628487834490508e-08 -1.1493395721791664e-06 0.9999999999993368 1.570800000003245
  children [
    DistanceSensor {
    }
    DEF BODY Shape {
      appearance PBRAppearance {
        baseColor 0 0.666667 0
        metalness 0
      }
      geometry Box {
        size 0.4 0.2 0.1
      }
    }
    HingeJoint {
      jointParameters HingeJointParameters {
        position -3.758758255755347e-07
        axis 0 1 0
        anchor 0.1 0.12 0
      }
      device [
        RotationalMotor {
          name "Wheel1"
        }
      ]
      endPoint Solid {
        translation 0.1 0.12 0
        rotation 0.9999999999999647 -1.8790074833068118e-07 1.879014359628332e-07 1.5707999856069208
        children [
          DEF WHEELSIZE Shape {
            appearance PBRAppearance {
              baseColor 0 0 0
              metalness 0
            }
            geometry Cylinder {
              height 0.04
              radius 0.1
            }
          }
        ]
        name "Wheel1"
        boundingObject USE WHEELSIZE
        physics DEF WheelPhysics Physics {
          density -1
          mass 1
        }
      }
    }
    HingeJoint {
      jointParameters HingeJointParameters {
        position -6.684814028052229e-07
        axis 0 1 0
        anchor 0.1 -0.12 0
      }
      device [
        RotationalMotor {
          name "Wheel2"
        }
      ]
      endPoint Solid {
        translation 0.09999999999756642 -0.12 3.6402200000012706e-06
        rotation 0.9999999999998924 -3.276573378922375e-07 3.277112492656089e-07 1.5707999857593695
        children [
          USE WHEELSIZE
        ]
        name "Wheel2"
        boundingObject USE WHEELSIZE
        physics USE WheelPhysics
      }
    }
    HingeJoint {
      jointParameters HingeJointParameters {
        position -6.702059438080107e-07
        axis 0 1 0
        anchor -0.1 -0.12 0
      }
      device [
        RotationalMotor {
          name "Wheel3"
        }
      ]
      endPoint Solid {
        translation -0.1 -0.12 0
        rotation 0.9999999999998875 -3.3506529844963604e-07 3.350665230656247e-07 1.5707999835204052
        children [
          USE WHEELSIZE
        ]
        name "Wheel3"
        boundingObject USE WHEELSIZE
        physics USE WheelPhysics
      }
    }
    HingeJoint {
      jointParameters HingeJointParameters {
        position -3.7415394788342553e-07
        axis 0 1 0
        anchor -0.1 0.12 0
      }
      device [
        RotationalMotor {
          name "Wheel4"
        }
      ]
      endPoint Solid {
        translation -0.1000000000015456 0.12 4.130470000004354e-06
        rotation 0.9999999999999631 -1.9216363728903724e-07 1.9221816916878313e-07 1.57079998822845
        children [
          USE WHEELSIZE
        ]
        name "Wheel4"
        boundingObject USE WHEELSIZE
        physics USE WheelPhysics
      }
    }
  ]
  name "Robot13"
  boundingObject USE BODY
  physics Physics {
  }
  controller "drive_robot"
  customData "green,10,9"
}
Robot {
  translation 10.94 -9.02 0.088806
  rotation 7.628487834490508e-08 -1.1493395721791664e-06 0.9999999999993368 1.570800000003245
  children [
    DistanceSensor {
    }
    DEF BODY Shape {
      appearance PBRAppearance {
        baseColor 0 0.666667 0
        metalness 0
      }
      geometry Box {
        size 0.4 0.2 0.1
      }
    }
    HingeJoint {
      jointParameters HingeJointParameters {
        position -3.758758255755347e-07
        axis 0 1 0
        anchor 0.1 0.12 0
      }
      device [
        RotationalMotor {
          name "Wheel1"
        }
      ]
      endPoint Solid {
        translation 0.1 0.12 0
        rotation 0.9999999999999647 -1.8790074833068118e-07 1.879014359628332e-07 1.5707999856069208
        children [
          DEF WHEELSIZE Shape {
            appearance PBRAppearance {
              baseColor 0 0 0
              metalness 0
            }
            geometry Cylinder {
              height 0.04
              radius 0.1
            }
          }
        ]
        name "Wheel1"
        boundingObject USE WHEELSIZE
        physics DEF WheelPhysics Physics {
          density -1
          mass 1
        }
      }
    }
    HingeJoint {
      jointParameters HingeJointParameters {
        position -6.684814028052229e-07
        axis 0 1 0
        anchor 0.1 -0.12 0
      }
      device [
        RotationalMotor {
          name "Wheel2"
        }
      ]
      endPoint Solid {
        translation 0.09999999999756642 -0.12 3.6402200000012706e-06
        rotation 0.9999999999998924 -3.276573378922375e-07 3.277112492656089e-07 1.5707999857593695
        children [
          USE WHEELSIZE
        ]
        name "Wheel2"
        boundingObject USE WHEELSIZE
        physics USE WheelPhysics
      }
    }
    HingeJoint {
      jointParameters HingeJointParameters {
        position -6.702059438080107e-07
        axis 0 1 0
        anchor -0.1 -0.12 0
      }
      device [
        RotationalMotor {
          name "Wheel3"
        }
      ]
      endPoint Solid {
        translation -0.1 -0.12 0
        rotation 0.9999999999998875 -3.3506529844963604e-07 3.350665230656247e-07 1.5707999835204052
        children [
          USE WHEELSIZE
        ]
        name "Wheel3"
        boundingObject USE WHEELSIZE
        physics USE WheelPhysics
      }
    }
    HingeJoint {
      jointParameters HingeJointParameters {
        position -3.7415394788342553e-07
        axis 0 1 0
        anchor -0.1 0.12 0
      }
      device [
        RotationalMotor {
          name "Wheel4"
        }
      ]
      endPoint Solid {
        translation -0.1000000000015456 0.12 4.130470000004354e-06
        rotation 0.9999999999999631 -1.9216363728903724e-07 1.9221816916878313e-07 1.57079998822845
        children [
          USE WHEELSIZE
        ]
        name "Wheel4"
        boundingObject USE WHEELSIZE
        physics USE WheelPhysics
      }
    }
  ]
  name "Robot14"
  boundingObject USE BODY
  physics Physics {
  }
  controller "drive_robot"
  customData "green,11,9"
}
