#VRML_SIM R2023b utf8

EXTERNPROTO "https://raw.githubusercontent.com/cyberbotics/webots/R2023a/projects/objects/backgrounds/protos/TexturedBackground.proto"
EXTERNPROTO "https://raw.githubusercontent.com/cyberbotics/webots/R2023a/projects/objects/backgrounds/protos/TexturedBackgroundLight.proto"
EXTERNPROTO "https://raw.githubusercontent.com/cyberbotics/webots/R2023b/projects/objects/floors/protos/RectangleArena.proto"

WorldInfo {
  basicTimeStep 16
}
Viewpoint {
  orientation 0.5577689732502473 -0.5650533177315544 -0.6079543737813947 4.210249013898877
  position 5.352516516606184 -6.3908512589156174 21.49125908056344
}
TexturedBackground {
  texture "morning_cloudy_empty"
}
TexturedBackgroundLight {
}
RectangleArena {
  translation 6 -4.5 0
  floorSize 13 10
  floorTileSize 2 2
  wallHeight 1.5
}
Robot {
  translation 12.03 -1.98 0.0988145
  rotation 7.628487834490508e-08 -1.1493395721791664e-06 0.9999999999993368 1.570800000003245
  children [
    DistanceSensor {
    }
    DEF BODY Shape {
      appearance PBRAppearance {
        baseColor 0.666667 0 0
        metalness 0
      }
      geometry Box {
        size 0.4 0.2 0.1
      }
    }
    HingeJoint {
      jointParameters HingeJointParameters {
        position -3.758758255755347e-07
        axis 0 1 0
        anchor 0.1 0.12 0
      }
      device [
        RotationalMotor {
          name "Wheel1"
        }
      ]
      endPoint Solid {
        translation 0.1 0.12 0
        rotation 0.9999999999999647 -1.8790074833068145e-07 1.8790143596283312e-07 1.5707999856069161
        children [
          DEF WHEELSIZE Shape {
            appearance PBRAppearance {
              baseColor 0 0 0
              metalness 0
            }
            geometry Cylinder {
              height 0.04
              radius 0.1
            }
          }
        ]
        name "Wheel1"
        boundingObject USE WHEELSIZE
        physics DEF WheelPhysics Physics {
          density -1
          mass 1
        }
      }
    }
    HingeJoint {
      jointParameters HingeJointParameters {
        position -6.684814028052229e-07
        axis 0 1 0
        anchor 0.1 -0.12 0
      }
      device [
        RotationalMotor {
          name "Wheel2"
        }
      ]
      endPoint Solid {
        translation 0.09999999999756642 -0.12 3.640220000001277e-06
        rotation 0.9999999999998924 -3.2765733789223654e-07 3.277112492656089e-07 1.5707999857593695
        children [
          USE WHEELSIZE
        ]
        name "Wheel2"
        boundingObject USE WHEELSIZE
        physics USE WheelPhysics
      }
    }
    HingeJoint {
      jointParameters HingeJointParameters {
        position -6.702059438080107e-07
        axis 0 1 0
        anchor -0.1 -0.12 0
      }
      device [
        RotationalMotor {
          name "Wheel3"
        }
      ]
      endPoint Solid {
        translation -0.1 -0.12 0
        rotation 0.9999999999998875 -3.3506529844963604e-07 3.350665230656247e-07 1.5707999835204052
        children [
          USE WHEELSIZE
        ]
        name "Wheel3"
        boundingObject USE WHEELSIZE
        physics USE WheelPhysics
      }
    }
    HingeJoint {
      jointParameters HingeJointParameters {
        position -3.7415394788342553e-07
        axis 0 1 0
        anchor -0.1 0.12 0
      }
      device [
        RotationalMotor {
          name "Wheel4"
        }
      ]
      endPoint Solid {
        translation -0.1000000000015456 0.12 4.130470000004341e-06
        rotation 0.9999999999999631 -1.9216363728903724e-07 1.9221816916878313e-07 1.57079998822845
        children [
          USE WHEELSIZE
        ]
        name "Wheel4"
        boundingObject USE WHEELSIZE
        physics USE WheelPhysics
      }
    }
  ]
  name "Robot15"
  boundingObject USE BODY
  physics Physics {
  }
  controller "drive_robot"
  customData "red,12,2"
}
Robot {
  translation 8.03 -8.97 0.088809
  rotation 7.628487834490508e-08 -1.1493395721791664e-06 0.9999999999993368 1.570800000003245
  children [
    DistanceSensor {
    }
    DEF BODY Shape {
      appearance PBRAppearance {
        baseColor 0.666667 0 0
        metalness 0
      }
      geometry Box {
        size 0.4 0.2 0.1
      }
    }
    HingeJoint {
      jointParameters HingeJointParameters {
        position -3.758758255755347e-07
        axis 0 1 0
        anchor 0.1 0.12 0
      }
      device [
        RotationalMotor {
          name "Wheel1"
        }
      ]
      endPoint Solid {
        translation 0.1 0.12 0
        rotation 0.9999999999999647 -1.8790074833068145e-07 1.8790143596283312e-07 1.5707999856069161
        children [
          DEF WHEELSIZE Shape {
            appearance PBRAppearance {
              baseColor 0 0 0
              metalness 0
            }
            geometry Cylinder {
              height 0.04
              radius 0.1
            }
          }
        ]
        name "Wheel1"
        boundingObject USE WHEELSIZE
        physics DEF WheelPhysics Physics {
          density -1
          mass 1
        }
      }
    }
    HingeJoint {
      jointParameters HingeJointParameters {
        position -6.684814028052229e-07
        axis 0 1 0
        anchor 0.1 -0.12 0
      }
      device [
        RotationalMotor {
          name "Wheel2"
        }
      ]
      endPoint Solid {
        translation 0.09999999999756642 -0.12 3.640220000001277e-06
        rotation 0.9999999999998924 -3.2765733789223654e-07 3.277112492656089e-07 1.5707999857593695
        children [
          USE WHEELSIZE
        ]
        name "Wheel2"
        boundingObject USE WHEELSIZE
        physics USE WheelPhysics
      }
    }
    HingeJoint {
      jointParameters HingeJointParameters {
        position -6.702059438080107e-07
        axis 0 1 0
        anchor -0.1 -0.12 0
      }
      device [
        RotationalMotor {
          name "Wheel3"
        }
      ]
      endPoint Solid {
        translation -0.1 -0.12 0
        rotation 0.9999999999998875 -3.3506529844963604e-07 3.350665230656247e-07 1.5707999835204052
        children [
          USE WHEELSIZE
        ]
        name "Wheel3"
        boundingObject USE WHEELSIZE
        physics USE WheelPhysics
      }
    }
    HingeJoint {
      jointParameters HingeJointParameters {
        position -3.7415394788342553e-07
        axis 0 1 0
        anchor -0.1 0.12 0
      }
      device [
        RotationalMotor {
          name "Wheel4"
        }
      ]
      endPoint Solid {
        translation -0.1000000000015456 0.12 4.130470000004341e-06
        rotation 0.9999999999999631 -1.9216363728903724e-07 1.9221816916878313e-07 1.57079998822845
        children [
          USE WHEELSIZE
        ]
        name "Wheel4"
        boundingObject USE WHEELSIZE
        physics USE WheelPhysics
      }
    }
  ]
  name "Robot16"
  boundingObject USE BODY
  physics Physics {
  }
  controller "drive_robot"
  customData "red,8,9"
}
Robot {
  translation 0.0200107 -9.02001 0.0987997
  rotation 7.628487834490508e-08 -1.1493395721791664e-06 0.9999999999993368 1.570800000003245
  children [
    DistanceSensor {
    }
    DEF BODY Shape {
      appearance PBRAppearance {
        baseColor 0.666667 0 0
        metalness 0
      }
      geometry Box {
        size 0.4 0.2 0.1
      }
    }
    HingeJoint {
      jointParameters HingeJointParameters {
        position -3.758758255755347e-07
        axis 0 1 0
        anchor 0.1 0.12 0
      }
      device [
        RotationalMotor {
          name "Wheel1"
        }
      ]
      endPoint Solid {
        translation 0.1 0.12 0
        rotation 0.9999999999999647 -1.8790074833068145e-07 1.8790143596283312e-07 1.5707999856069161
        children [
          DEF WHEELSIZE Shape {
            appearance PBRAppearance {
              baseColor 0 0 0
              metalness 0
            }
            geometry Cylinder {
              height 0.04
              radius 0.1
            }
          }
        ]
        name "Wheel1"
        boundingObject USE WHEELSIZE
        physics DEF WheelPhysics Physics {
          density -1
          mass 1
        }
      }
    }
    HingeJoint {
      jointParameters HingeJointParameters {
        position -6.684814028052229e-07
        axis 0 1 0
        anchor 0.1 -0.12 0
      }
      device [
        RotationalMotor {
          name "Wheel2"
        }
      ]
      endPoint Solid {
        translation 0.09999999999756642 -0.12 3.640220000001277e-06
        rotation 0.9999999999998924 -3.2765733789223654e-07 3.277112492656089e-07 1.5707999857593695
        children [
          USE WHEELSIZE
        ]
        name "Wheel2"
        boundingObject USE WHEELSIZE
        physics USE WheelPhysics
      }
    }
    HingeJoint {
      jointParameters HingeJointParameters {
        position -6.702059438080107e-07
        axis 0 1 0
        anchor -0.1 -0.12 0
      }
      device [
        RotationalMotor {
          name "Wheel3"
        }
      ]
      endPoint Solid {
        translation -0.1 -0.12 0
        rotation 0.9999999999998875 -3.3506529844963604e-07 3.350665230656247e-07 1.5707999835204052
        children [
          USE WHEELSIZE
        ]
        name "Wheel3"
        boundingObject USE WHEELSIZE
        physics USE WheelPhysics
      }
    }
    HingeJoint {
      jointParameters HingeJointParameters {
        position -3.7415394788342553e-07
        axis 0 1 0
        anchor -0.1 0.12 0
      }
      device [
        RotationalMotor {
          name "Wheel4"
        }
      ]
      endPoint Solid {
        translation -0.1000000000015456 0.12 4.130470000004341e-06
        rotation 0.9999999999999631 -1.9216363728903724e-07 1.9221816916878313e-07 1.57079998822845
        children [
          USE WHEELSIZE
        ]
        name "Wheel4"
        boundingObject USE WHEELSIZE
        physics USE WheelPhysics
      }
    }
  ]
  name "Robot17"
  boundingObject USE BODY
  physics Physics {
  }
  controller "drive_robot"
  customData "red,0,9"
}
Robot {
  translation 5.12 -0.02 0.108806
  rotation 7.628487834490508e-08 -1.1493395721791664e-06 0.9999999999993368 1.570800000003245
  children [
    DistanceSensor {
    }
    DEF BODY Shape {
      appearance PBRAppearance {
        baseColor 0.666667 0 0
        metalness 0
      }
      geometry Box {
        size 0.4 0.2 0.1
      }
    }
    HingeJoint {
      jointParameters HingeJointParameters {
        position -3.758758255755347e-07
        axis 0 1 0
        anchor 0.1 0.12 0
      }
      device [
        RotationalMotor {
          name "Wheel1"
        }
      ]
      endPoint Solid {
        translation 0.1 0.12 0
        rotation 0.9999999999999647 -1.8790074833068142e-07 1.879014359628331e-07 1.5707999856069164
        children [
          DEF WHEELSIZE Shape {
            appearance PBRAppearance {
              baseColor 0 0 0
              metalness 0
            }
            geometry Cylinder {
              height 0.04
              radius 0.1
            }
          }
        ]
        name "Wheel1"
        boundingObject USE WHEELSIZE
        physics DEF WheelPhysics Physics {
          density -1
          mass 1
        }
      }
    }
    HingeJoint {
      jointParameters HingeJointParameters {
        position -6.684814028052229e-07
        axis 0 1 0
        anchor 0.1 -0.12 0
      }
      device [
        RotationalMotor {
          name "Wheel2"
        }
      ]
      endPoint Solid {
        translation 0.09999999999756642 -0.12 3.6402200000012765e-06
        rotation 0.9999999999998924 -3.276573378922366e-07 3.277112492656089e-07 1.5707999857593695
        children [
          USE WHEELSIZE
        ]
        name "Wheel2"
        boundingObject USE WHEELSIZE
        physics USE WheelPhysics
      }
    }
    HingeJoint {
      jointParameters HingeJointParameters {
        position -6.702059438080107e-07
        axis 0 1 0
        anchor -0.1 -0.12 0
      }
      device [
        RotationalMotor {
          name "Wheel3"
        }
      ]
      endPoint Solid {
        translation -0.1 -0.12 0
        rotation 0.9999999999998875 -3.3506529844963604e-07 3.350665230656247e-07 1.5707999835204052
        children [
          USE WHEELSIZE
        ]
        name "Wheel3"
        boundingObject USE WHEELSIZE
        physics USE WheelPhysics
      }
    }
    HingeJoint {
      jointParameters HingeJointParameters {
        position -3.7415394788342553e-07
        axis 0 1 0
        anchor -0.1 0.12 0
      }
      device [
        RotationalMotor {
          name "Wheel4"
        }
      ]
      endPoint Solid {
        translation -0.1000000000015456 0.12 4.130470000004342e-06
        rotation 0.9999999999999631 -1.9216363728903724e-07 1.9221816916878313e-07 1.57079998822845
        children [
          USE WHEELSIZE
        ]
        name "Wheel4"
        boundingObject USE WHEELSIZE
        physics USE WheelPhysics
      }
    }
  ]
  name "Robot18"
  boundingObject USE BODY
  physics Physics {
  }
  controller "drive_robot"
  customData "red,5,0"
}
Robot {
  translation 3e-05 -3.14 0.0988088
  rotation 7.62849182656497e-08 -1.1493396116374477e-06 0.9999999999993368 1.5708000000005344
  children [
    DistanceSensor {
    }
    DEF BODY Shape {
      appearance PBRAppearance {
        baseColor 0.666667 0 0
        metalness 0
      }
      geometry Box {
        size 0.4 0.2 0.1
      }
    }
    HingeJoint {
      jointParameters HingeJointParameters {
        position 2.917926097885631e-11
        axis 0 1 0
        anchor 0.1 0.12 0
      }
      device [
        RotationalMotor {
          name "Wheel1"
        }
      ]
      endPoint Solid {
        translation 0.1 0.12 0
        rotation 1 5.762915684194754e-10 -5.762935395824222e-10 1.5707999856068906
        children [
          DEF WHEELSIZE Shape {
            appearance PBRAppearance {
              baseColor 0 0 0
              metalness 0
            }
            geometry Cylinder {
              height 0.04
              radius 0.1
            }
          }
        ]
        name "Wheel1"
        boundingObject USE WHEELSIZE
        physics DEF WheelPhysics Physics {
          density -1
          mass 1
        }
      }
    }
    HingeJoint {
      jointParameters HingeJointParameters {
        position -9.724587776652118e-15
        axis 0 1 0
        anchor 0.1 -0.12 0
      }
      device [
        RotationalMotor {
          name "Wheel2"
        }
      ]
      endPoint Solid {
        translation 0.09999999999999984 -0.12 3.6402200000020727e-06
        rotation 1 6.581999161986383e-09 -6.529310760677428e-09 1.5707999857592636
        children [
          USE WHEELSIZE
        ]
        name "Wheel2"
        boundingObject USE WHEELSIZE
        physics USE WheelPhysics
      }
    }
    HingeJoint {
      jointParameters HingeJointParameters {
        position 2.9156745642340747e-11
        axis 0 1 0
        anchor -0.1 -0.12 0
      }
      device [
        RotationalMotor {
          name "Wheel3"
        }
      ]
      endPoint Solid {
        translation -0.1 -0.12 0
        rotation 1 5.758464504966758e-10 -5.75849184250711e-10 1.570799983520293
        children [
          USE WHEELSIZE
        ]
        name "Wheel3"
        boundingObject USE WHEELSIZE
        physics USE WheelPhysics
      }
    }
    HingeJoint {
      jointParameters HingeJointParameters {
        position -1.2293132562136235e-14
        axis 0 1 0
        anchor -0.1 0.12 0
      }
      device [
        RotationalMotor {
          name "Wheel4"
        }
      ]
      endPoint Solid {
        translation -0.10000000000000017 0.12 4.130470000004657e-06
        rotation 1 -5.087527429972476e-09 5.1413743417256236e-09 1.5707999882284138
        children [
          USE WHEELSIZE
        ]
        name "Wheel4"
        boundingObject USE WHEELSIZE
        physics USE WheelPhysics
      }
    }
  ]
  name "Robot6"
  boundingObject USE BODY
  physics Physics {
  }
  controller "drive_robot"
  customData "red,0,3"
}
Robot {
  translation -0.129967 -6.01 0.098808
  rotation 7.628476053430804e-08 -1.149339785963148e-06 0.9999999999993366 1.5707997131026343
  children [
    DistanceSensor {
    }
    DEF BODY Shape {
      appearance PBRAppearance {
        baseColor 0 1 0
        metalness 0
      }
      geometry Box {
        size 0.4 0.2 0.1
      }
    }
    HingeJoint {
      jointParameters HingeJointParameters {
        position 3.8298616043356944e-08
        axis 0 1 0
        anchor 0.1 0.12 0
      }
      device [
        RotationalMotor {
          name "Wheel1"
        }
      ]
      endPoint Solid {
        translation 0.1 0.12 0
        rotation 0.9999999999999996 1.914923811509773e-08 -1.9149308041304586e-08 1.5707999856068906
        children [
          DEF WHEELSIZE Shape {
            appearance PBRAppearance {
              baseColor 0 0 0
              metalness 0
            }
            geometry Cylinder {
              height 0.04
              radius 0.1
            }
          }
        ]
        name "Wheel1"
        boundingObject USE WHEELSIZE
        physics DEF WheelPhysics Physics {
          density -1
          mass 1
        }
      }
    }
    HingeJoint {
      jointParameters HingeJointParameters {
        position -3.176474550059538e-08
        axis 0 1 0
        anchor 0.1 -0.12 0
      }
      device [
        RotationalMotor {
          name "Wheel2"
        }
      ]
      endPoint Solid {
        translation 0.09999999999988438 -0.12 3.6402200000020833e-06
        rotation 1 -9.27824189441685e-09 9.330988327888827e-09 1.5707999857592636
        children [
          USE WHEELSIZE
        ]
        name "Wheel2"
        boundingObject USE WHEELSIZE
        physics USE WheelPhysics
      }
    }
    HingeJoint {
      jointParameters HingeJointParameters {
        position 2.9143387833612897e-08
        axis 0 1 0
        anchor -0.1 -0.12 0
      }
      device [
        RotationalMotor {
          name "Wheel3"
        }
      ]
      endPoint Solid {
        translation -0.1 -0.12 0
        rotation 0.9999999999999997 1.4571640082689296e-08 -1.4571693995310926e-08 1.5707999835202937
        children [
          USE WHEELSIZE
        ]
        name "Wheel3"
        boundingObject USE WHEELSIZE
        physics USE WheelPhysics
      }
    }
    HingeJoint {
      jointParameters HingeJointParameters {
        position -3.566959438927597e-08
        axis 0 1 0
        anchor -0.1 0.12 0
      }
      device [
        RotationalMotor {
          name "Wheel4"
        }
      ]
      endPoint Solid {
        translation -0.10000000000014733 0.12 4.1304700000047045e-06
        rotation 0.9999999999999997 -2.2900123234135338e-08 2.2954035365643093e-08 1.5707999882284052
        children [
          USE WHEELSIZE
        ]
        name "Wheel4"
        boundingObject USE WHEELSIZE
        physics USE WheelPhysics
      }
    }
  ]
  name "Robot3"
  boundingObject USE BODY
  physics Physics {
  }
  controller "drive_robot"
  customData "green,0,6"
}
Robot {
  translation 4.02003 -8.98 0.0988083
  rotation 7.628491710494937e-08 -1.1493396128274498e-06 0.9999999999993368 1.5708000000005298
  children [
    DistanceSensor {
    }
    DEF BODY Shape {
      appearance PBRAppearance {
        baseColor 0 1 0
        metalness 0
      }
      geometry Box {
        size 0.4 0.2 0.1
      }
    }
    HingeJoint {
      jointParameters HingeJointParameters {
        position 1.4596357779530014e-11
        axis 0 1 0
        anchor 0.1 0.12 0
      }
      device [
        RotationalMotor {
          name "Wheel1"
        }
      ]
      endPoint Solid {
        translation 0.1 0.12 0
        rotation 1 2.77329940120636e-10 -2.773308174371906e-10 1.5707999856068906
        children [
          DEF WHEELSIZE Shape {
            appearance PBRAppearance {
              baseColor 0 0 0
              metalness 0
            }
            geometry Cylinder {
              height 0.04
              radius 0.1
            }
          }
        ]
        name "Wheel1"
        boundingObject USE WHEELSIZE
        physics DEF WheelPhysics Physics {
          density -1
          mass 1
        }
      }
    }
    HingeJoint {
      jointParameters HingeJointParameters {
        position -1.461586407458526e-11
        axis 0 1 0
        anchor 0.1 -0.12 0
      }
      device [
        RotationalMotor {
          name "Wheel2"
        }
      ]
      endPoint Solid {
        translation 0.0999999999999979 -0.12 3.6402200000020727e-06
        rotation 1 6.3263723416317945e-09 -6.273683004991726e-09 1.5707999857592636
        children [
          USE WHEELSIZE
        ]
        name "Wheel2"
        boundingObject USE WHEELSIZE
        physics USE WheelPhysics
      }
    }
    HingeJoint {
      jointParameters HingeJointParameters {
        position 1.4584619329972877e-11
        axis 0 1 0
        anchor -0.1 -0.12 0
      }
      device [
        RotationalMotor {
          name "Wheel3"
        }
      ]
      endPoint Solid {
        translation -0.1 -0.12 0
        rotation 1 2.77106204432971e-10 -2.771078457739638e-10 1.570799983520293
        children [
          USE WHEELSIZE
        ]
        name "Wheel3"
        boundingObject USE WHEELSIZE
        physics USE WheelPhysics
      }
    }
    HingeJoint {
      jointParameters HingeJointParameters {
        position -1.4630963107720163e-11
        axis 0 1 0
        anchor -0.1 0.12 0
      }
      device [
        RotationalMotor {
          name "Wheel4"
        }
      ]
      endPoint Solid {
        translation -0.10000000000000211 0.12 4.130470000004657e-06
        rotation 1 -5.343378621514787e-09 5.397226470051769e-09 1.5707999882284138
        children [
          USE WHEELSIZE
        ]
        name "Wheel4"
        boundingObject USE WHEELSIZE
        physics USE WheelPhysics
      }
    }
  ]
  name "Robot4"
  boundingObject USE BODY
  physics Physics {
  }
  controller "drive_robot"
  customData "green,4,9"
}
Robot {
  translation 4.02003 -0.02 0.0988176
  rotation 7.628487834490508e-08 -1.1493395721791664e-06 0.9999999999993368 1.570800000003245
  children [
    DistanceSensor {
    }
    DEF BODY Shape {
      appearance PBRAppearance {
        baseColor 0.666667 0 0
        metalness 0
      }
      geometry Box {
        size 0.4 0.2 0.1
      }
    }
    HingeJoint {
      jointParameters HingeJointParameters {
        position -3.758758255755347e-07
        axis 0 1 0
        anchor 0.1 0.12 0
      }
      device [
        RotationalMotor {
          name "Wheel1"
        }
      ]
      endPoint Solid {
        translation 0.1 0.12 0
        rotation 0.9999999999999647 -1.8790074833068145e-07 1.8790143596283312e-07 1.5707999856069161
        children [
          DEF WHEELSIZE Shape {
            appearance PBRAppearance {
              baseColor 0 0 0
              metalness 0
            }
            geometry Cylinder {
              height 0.04
              radius 0.1
            }
          }
        ]
        name "Wheel1"
        boundingObject USE WHEELSIZE
        physics DEF WheelPhysics Physics {
          density -1
          mass 1
        }
      }
    }
    HingeJoint {
      jointParameters HingeJointParameters {
        position -6.684814028052229e-07
        axis 0 1 0
        anchor 0.1 -0.12 0
      }
      device [
        RotationalMotor {
          name "Wheel2"
        }
      ]
      endPoint Solid {
        translation 0.09999999999756642 -0.12 3.640220000001277e-06
        rotation 0.9999999999998924 -3.2765733789223654e-07 3.277112492656089e-07 1.5707999857593695
        children [
          USE WHEELSIZE
        ]
        name "Wheel2"
        boundingObject USE WHEELSIZE
        physics USE WheelPhysics
      }
    }
    HingeJoint {
      jointParameters HingeJointParameters {
        position -6.702059438080107e-07
        axis 0 1 0
        anchor -0.1 -0.12 0
      }
      device [
        RotationalMotor {
          name "Wheel3"
        }
      ]
      endPoint Solid {
        translation -0.1 -0.12 0
        rotation 0.9999999999998875 -3.3506529844963604e-07 3.350665230656247e-07 1.5707999835204052
        children [
          USE WHEELSIZE
        ]
        name "Wheel3"
        boundingObject USE WHEELSIZE
        physics USE WheelPhysics
      }
    }
    HingeJoint {
      jointParameters HingeJointParameters {
        position -3.7415394788342553e-07
        axis 0 1 0
        anchor -0.1 0.12 0
      }
      device [
        RotationalMotor {
          name "Wheel4"
        }
      ]
      endPoint Solid {
        translation -0.1000000000015456 0.12 4.130470000004341e-06
        rotation 0.9999999999999631 -1.9216363728903724e-07 1.9221816916878313e-07 1.57079998822845
        children [
          USE WHEELSIZE
        ]
        name "Wheel4"
        boundingObject USE WHEELSIZE
        physics USE WheelPhysics
      }
    }
  ]
  name "Robot5"
  boundingObject USE BODY
  physics Physics {
  }
  controller "drive_robot"
  customData "red,4,0"
}
Robot {
  translation 1.04003 -1.15 0.0988112
  rotation 7.628487834490508e-08 -1.1493395721791664e-06 0.9999999999993368 1.570800000003245
  children [
    DistanceSensor {
    }
    DEF BODY Shape {
      appearance PBRAppearance {
        baseColor 0 0.333333 1
        metalness 0
      }
      geometry Box {
        size 0.4 0.2 0.1
      }
    }
    HingeJoint {
      jointParameters HingeJointParameters {
        position -3.758758255755347e-07
        axis 0 1 0
        anchor 0.1 0.12 0
      }
      device [
        RotationalMotor {
          name "Wheel1"
        }
      ]
      endPoint Solid {
        translation 0.1 0.12 0
        rotation 0.9999999999999647 -1.8790074833068145e-07 1.8790143596283312e-07 1.5707999856069161
        children [
          DEF WHEELSIZE Shape {
            appearance PBRAppearance {
              baseColor 0 0 0
              metalness 0
            }
            geometry Cylinder {
              height 0.04
              radius 0.1
            }
          }
        ]
        name "Wheel1"
        boundingObject USE WHEELSIZE
        physics DEF WheelPhysics Physics {
          density -1
          mass 1
        }
      }
    }
    HingeJoint {
      jointParameters HingeJointParameters {
        position -6.684814028052229e-07
        axis 0 1 0
        anchor 0.1 -0.12 0
      }
      device [
        RotationalMotor {
          name "Wheel2"
        }
      ]
      endPoint Solid {
        translation 0.09999999999756642 -0.12 3.640220000001277e-06
        rotation 0.9999999999998924 -3.2765733789223654e-07 3.277112492656089e-07 1.5707999857593695
        children [
          USE WHEELSIZE
        ]
        name "Wheel2"
        boundingObject USE WHEELSIZE
        physics USE WheelPhysics
      }
    }
    HingeJoint {
      jointParameters HingeJointParameters {
        position -6.702059438080107e-07
        axis 0 1 0
        anchor -0.1 -0.12 0
      }
      device [
        RotationalMotor {
          name "Wheel3"
        }
      ]
      endPoint Solid {
        translation -0.1 -0.12 0
        rotation 0.9999999999998875 -3.3506529844963604e-07 3.350665230656247e-07 1.5707999835204052
        children [
          USE WHEELSIZE
        ]
        name "Wheel3"
        boundingObject USE WHEELSIZE
        physics USE WheelPhysics
      }
    }
    HingeJoint {
      jointParameters HingeJointParameters {
        position -3.7415394788342553e-07
        axis 0 1 0
        anchor -0.1 0.12 0
      }
      device [
        RotationalMotor {
          name "Wheel4"
        }
      ]
      endPoint Solid {
        translation -0.1000000000015456 0.12 4.130470000004341e-06
        rotation 0.9999999999999631 -1.9216363728903724e-07 1.9221816916878313e-07 1.57079998822845
        children [
          USE WHEELSIZE
        ]
        name "Wheel4"
        boundingObject USE WHEELSIZE
        physics USE WheelPhysics
      }
    }
  ]
  name "Robot7"
  boundingObject USE BODY
  physics Physics {
  }
  controller "drive_robot"
  customData "blue,1,1"
}
Robot {
  translation 4.99003 -8.94 0.108806
  rotation 7.628487834490508e-08 -1.1493395721791664e-06 0.9999999999993368 1.570800000003245
  children [
    DistanceSensor {
    }
    DEF BODY Shape {
      appearance PBRAppearance {
        baseColor 0 0.333333 1
        metalness 0
      }
      geometry Box {
        size 0.4 0.2 0.1
      }
    }
    HingeJoint {
      jointParameters HingeJointParameters {
        position -3.758758255755347e-07
        axis 0 1 0
        anchor 0.1 0.12 0
      }
      device [
        RotationalMotor {
          name "Wheel1"
        }
      ]
      endPoint Solid {
        translation 0.1 0.12 0
        rotation 0.9999999999999647 -1.8790074833068142e-07 1.879014359628331e-07 1.5707999856069164
        children [
          DEF WHEELSIZE Shape {
            appearance PBRAppearance {
              baseColor 0 0 0
              metalness 0
            }
            geometry Cylinder {
              height 0.04
              radius 0.1
            }
          }
        ]
        name "Wheel1"
        boundingObject USE WHEELSIZE
        physics DEF WheelPhysics Physics {
          density -1
          mass 1
        }
      }
    }
    HingeJoint {
      jointParameters HingeJointParameters {
        position -6.684814028052229e-07
        axis 0 1 0
        anchor 0.1 -0.12 0
      }
      device [
        RotationalMotor {
          name "Wheel2"
        }
      ]
      endPoint Solid {
        translation 0.09999999999756642 -0.12 3.6402200000012765e-06
        rotation 0.9999999999998924 -3.276573378922366e-07 3.277112492656089e-07 1.5707999857593695
        children [
          USE WHEELSIZE
        ]
        name "Wheel2"
        boundingObject USE WHEELSIZE
        physics USE WheelPhysics
      }
    }
    HingeJoint {
      jointParameters HingeJointParameters {
        position -6.702059438080107e-07
        axis 0 1 0
        anchor -0.1 -0.12 0
      }
      device [
        RotationalMotor {
          name "Wheel3"
        }
      ]
      endPoint Solid {
        translation -0.1 -0.12 0
        rotation 0.9999999999998875 -3.3506529844963604e-07 3.350665230656247e-07 1.5707999835204052
        children [
          USE WHEELSIZE
        ]
        name "Wheel3"
        boundingObject USE WHEELSIZE
        physics USE WheelPhysics
      }
    }
    HingeJoint {
      jointParameters HingeJointParameters {
        position -3.7415394788342553e-07
        axis 0 1 0
        anchor -0.1 0.12 0
      }
      device [
        RotationalMotor {
          name "Wheel4"
        }
      ]
      endPoint Solid {
        translation -0.1000000000015456 0.12 4.130470000004342e-06
        rotation 0.9999999999999631 -1.9216363728903724e-07 1.9221816916878313e-07 1.57079998822845
        children [
          USE WHEELSIZE
        ]
        name "Wheel4"
        boundingObject USE WHEELSIZE
        physics USE WheelPhysics
      }
    }
  ]
  name "Robot8"
  boundingObject USE BODY
  physics Physics {
  }
  controller "drive_robot"
  customData "blue,5,9"
}
Robot {
  translation 10.95 -6.94 0.10881
  rotation 7.628487834490508e-08 -1.1493395721791664e-06 0.9999999999993368 1.570800000003245
  children [
    DistanceSensor {
    }
    DEF BODY Shape {
      appearance PBRAppearance {
        baseColor 0 0.333333 1
        metalness 0
      }
      geometry Box {
        size 0.4 0.2 0.1
      }
    }
    HingeJoint {
      jointParameters HingeJointParameters {
        position -3.758758255755347e-07
        axis 0 1 0
        anchor 0.1 0.12 0
      }
      device [
        RotationalMotor {
          name "Wheel1"
        }
      ]
      endPoint Solid {
        translation 0.1 0.12 0
        rotation 0.9999999999999647 -1.8790074833068142e-07 1.879014359628331e-07 1.5707999856069164
        children [
          DEF WHEELSIZE Shape {
            appearance PBRAppearance {
              baseColor 0 0 0
              metalness 0
            }
            geometry Cylinder {
              height 0.04
              radius 0.1
            }
          }
        ]
        name "Wheel1"
        boundingObject USE WHEELSIZE
        physics DEF WheelPhysics Physics {
          density -1
          mass 1
        }
      }
    }
    HingeJoint {
      jointParameters HingeJointParameters {
        position -6.684814028052229e-07
        axis 0 1 0
        anchor 0.1 -0.12 0
      }
      device [
        RotationalMotor {
          name "Wheel2"
        }
      ]
      endPoint Solid {
        translation 0.09999999999756642 -0.12 3.6402200000012765e-06
        rotation 0.9999999999998924 -3.276573378922366e-07 3.277112492656089e-07 1.5707999857593695
        children [
          USE WHEELSIZE
        ]
        name "Wheel2"
        boundingObject USE WHEELSIZE
        physics USE WheelPhysics
      }
    }
    HingeJoint {
      jointParameters HingeJointParameters {
        position -6.702059438080107e-07
        axis 0 1 0
        anchor -0.1 -0.12 0
      }
      device [
        RotationalMotor {
          name "Wheel3"
        }
      ]
      endPoint Solid {
        translation -0.1 -0.12 0
        rotation 0.9999999999998875 -3.3506529844963604e-07 3.350665230656247e-07 1.5707999835204052
        children [
          USE WHEELSIZE
        ]
        name "Wheel3"
        boundingObject USE WHEELSIZE
        physics USE WheelPhysics
      }
    }
    HingeJoint {
      jointParameters HingeJointParameters {
        position -3.7415394788342553e-07
        axis 0 1 0
        anchor -0.1 0.12 0
      }
      device [
        RotationalMotor {
          name "Wheel4"
        }
      ]
      endPoint Solid {
        translation -0.1000000000015456 0.12 4.130470000004342e-06
        rotation 0.9999999999999631 -1.9216363728903724e-07 1.9221816916878313e-07 1.57079998822845
        children [
          USE WHEELSIZE
        ]
        name "Wheel4"
        boundingObject USE WHEELSIZE
        physics USE WheelPhysics
      }
    }
  ]
  name "Robot9"
  boundingObject USE BODY
  physics Physics {
  }
  controller "drive_robot"
  customData "blue,11,7"
}
Robot {
  translation 1.02003 -8.95 0.0988001
  rotation 7.628487834490508e-08 -1.1493395721791664e-06 0.9999999999993368 1.570800000003245
  children [
    DistanceSensor {
    }
    DEF BODY Shape {
      appearance PBRAppearance {
        baseColor 0 0.333333 1
        metalness 0
      }
      geometry Box {
        size 0.4 0.2 0.1
      }
    }
    HingeJoint {
      jointParameters HingeJointParameters {
        position -3.758758255755347e-07
        axis 0 1 0
        anchor 0.1 0.12 0
      }
      device [
        RotationalMotor {
          name "Wheel1"
        }
      ]
      endPoint Solid {
        translation 0.1 0.12 0
        rotation 0.9999999999999647 -1.8790074833068145e-07 1.8790143596283312e-07 1.5707999856069161
        children [
          DEF WHEELSIZE Shape {
            appearance PBRAppearance {
              baseColor 0 0 0
              metalness 0
            }
            geometry Cylinder {
              height 0.04
              radius 0.1
            }
          }
        ]
        name "Wheel1"
        boundingObject USE WHEELSIZE
        physics DEF WheelPhysics Physics {
          density -1
          mass 1
        }
      }
    }
    HingeJoint {
      jointParameters HingeJointParameters {
        position -6.684814028052229e-07
        axis 0 1 0
        anchor 0.1 -0.12 0
      }
      device [
        RotationalMotor {
          name "Wheel2"
        }
      ]
      endPoint Solid {
        translation 0.09999999999756642 -0.12 3.640220000001277e-06
        rotation 0.9999999999998924 -3.2765733789223654e-07 3.277112492656089e-07 1.5707999857593695
        children [
          USE WHEELSIZE
        ]
        name "Wheel2"
        boundingObject USE WHEELSIZE
        physics USE WheelPhysics
      }
    }
    HingeJoint {
      jointParameters HingeJointParameters {
        position -6.702059438080107e-07
        axis 0 1 0
        anchor -0.1 -0.12 0
      }
      device [
        RotationalMotor {
          name "Wheel3"
        }
      ]
      endPoint Solid {
        translation -0.1 -0.12 0
        rotation 0.9999999999998875 -3.3506529844963604e-07 3.350665230656247e-07 1.5707999835204052
        children [
          USE WHEELSIZE
        ]
        name "Wheel3"
        boundingObject USE WHEELSIZE
        physics USE WheelPhysics
      }
    }
    HingeJoint {
      jointParameters HingeJointParameters {
        position -3.7415394788342553e-07
        axis 0 1 0
        anchor -0.1 0.12 0
      }
      device [
        RotationalMotor {
          name "Wheel4"
        }
      ]
      endPoint Solid {
        translation -0.1000000000015456 0.12 4.130470000004341e-06
        rotation 0.9999999999999631 -1.9216363728903724e-07 1.9221816916878313e-07 1.57079998822845
        children [
          USE WHEELSIZE
        ]
        name "Wheel4"
        boundingObject USE WHEELSIZE
        physics USE WheelPhysics
      }
    }
  ]
  name "Robot10"
  boundingObject USE BODY
  physics Physics {
  }
  controller "drive_robot"
  customData "blue,1,9"
}
Robot {
  translation 2.11003 -9 0.0988001
  rotation 7.628487834490508e-08 -1.1493395721791664e-06 0.9999999999993368 1.570800000003245
  children [
    DistanceSensor {
    }
    DEF BODY Shape {
      appearance PBRAppearance {
        baseColor 0 0.333333 1
        metalness 0
      }
      geometry Box {
        size 0.4 0.2 0.1
      }
    }
    HingeJoint {
      jointParameters HingeJointParameters {
        position -3.758758255755347e-07
        axis 0 1 0
        anchor 0.1 0.12 0
      }
      device [
        RotationalMotor {
          name "Wheel1"
        }
      ]
      endPoint Solid {
        translation 0.1 0.12 0
        rotation 0.9999999999999647 -1.8790074833068145e-07 1.8790143596283312e-07 1.5707999856069161
        children [
          DEF WHEELSIZE Shape {
            appearance PBRAppearance {
              baseColor 0 0 0
              metalness 0
            }
            geometry Cylinder {
              height 0.04
              radius 0.1
            }
          }
        ]
        name "Wheel1"
        boundingObject USE WHEELSIZE
        physics DEF WheelPhysics Physics {
          density -1
          mass 1
        }
      }
    }
    HingeJoint {
      jointParameters HingeJointParameters {
        position -6.684814028052229e-07
        axis 0 1 0
        anchor 0.1 -0.12 0
      }
      device [
        RotationalMotor {
          name "Wheel2"
        }
      ]
      endPoint Solid {
        translation 0.09999999999756642 -0.12 3.640220000001277e-06
        rotation 0.9999999999998924 -3.2765733789223654e-07 3.277112492656089e-07 1.5707999857593695
        children [
          USE WHEELSIZE
        ]
        name "Wheel2"
        boundingObject USE WHEELSIZE
        physics USE WheelPhysics
      }
    }
    HingeJoint {
      jointParameters HingeJointParameters {
        position -6.702059438080107e-07
        axis 0 1 0
        anchor -0.1 -0.12 0
      }
      device [
        RotationalMotor {
          name "Wheel3"
        }
      ]
      endPoint Solid {
        translation -0.1 -0.12 0
        rotation 0.9999999999998875 -3.3506529844963604e-07 3.350665230656247e-07 1.5707999835204052
        children [
          USE WHEELSIZE
        ]
        name "Wheel3"
        boundingObject USE WHEELSIZE
        physics USE WheelPhysics
      }
    }
    HingeJoint {
      jointParameters HingeJointParameters {
        position -3.7415394788342553e-07
        axis 0 1 0
        anchor -0.1 0.12 0
      }
      device [
        RotationalMotor {
          name "Wheel4"
        }
      ]
      endPoint Solid {
        translation -0.1000000000015456 0.12 4.130470000004341e-06
        rotation 0.9999999999999631 -1.9216363728903724e-07 1.9221816916878313e-07 1.57079998822845
        children [
          USE WHEELSIZE
        ]
        name "Wheel4"
        boundingObject USE WHEELSIZE
        physics USE WheelPhysics
      }
    }
  ]
  name "Robot11"
  boundingObject USE BODY
  physics Physics {
  }
  controller "drive_robot"
  customData "blue,2,9"
}
Robot {
  translation 9.11003 -0.16 0.0988163
  rotation 7.628487834490508e-08 -1.1493395721791664e-06 0.9999999999993368 1.570800000003245
  children [
    DistanceSensor {
    }
    DEF BODY Shape {
      appearance PBRAppearance {
        baseColor 0 0.666667 0
        metalness 0
      }
      geometry Box {
        size 0.4 0.2 0.1
      }
    }
    HingeJoint {
      jointParameters HingeJointParameters {
        position -3.758758255755347e-07
        axis 0 1 0
        anchor 0.1 0.12 0
      }
      device [
        RotationalMotor {
          name "Wheel1"
        }
      ]
      endPoint Solid {
        translation 0.1 0.12 0
        rotation 0.9999999999999647 -1.8790074833068145e-07 1.8790143596283312e-07 1.5707999856069161
        children [
          DEF WHEELSIZE Shape {
            appearance PBRAppearance {
              baseColor 0 0 0
              metalness 0
            }
            geometry Cylinder {
              height 0.04
              radius 0.1
            }
          }
        ]
        name "Wheel1"
        boundingObject USE WHEELSIZE
        physics DEF WheelPhysics Physics {
          density -1
          mass 1
        }
      }
    }
    HingeJoint {
      jointParameters HingeJointParameters {
        position -6.684814028052229e-07
        axis 0 1 0
        anchor 0.1 -0.12 0
      }
      device [
        RotationalMotor {
          name "Wheel2"
        }
      ]
      endPoint Solid {
        translation 0.09999999999756642 -0.12 3.640220000001277e-06
        rotation 0.9999999999998924 -3.2765733789223654e-07 3.277112492656089e-07 1.5707999857593695
        children [
          USE WHEELSIZE
        ]
        name "Wheel2"
        boundingObject USE WHEELSIZE
        physics USE WheelPhysics
      }
    }
    HingeJoint {
      jointParameters HingeJointParameters {
        position -6.702059438080107e-07
        axis 0 1 0
        anchor -0.1 -0.12 0
      }
      device [
        RotationalMotor {
          name "Wheel3"
        }
      ]
      endPoint Solid {
        translation -0.1 -0.12 0
        rotation 0.9999999999998875 -3.3506529844963604e-07 3.350665230656247e-07 1.5707999835204052
        children [
          USE WHEELSIZE
        ]
        name "Wheel3"
        boundingObject USE WHEELSIZE
        physics USE WheelPhysics
      }
    }
    HingeJoint {
      jointParameters HingeJointParameters {
        position -3.7415394788342553e-07
        axis 0 1 0
        anchor -0.1 0.12 0
      }
      device [
        RotationalMotor {
          name "Wheel4"
        }
      ]
      endPoint Solid {
        translation -0.1000000000015456 0.12 4.130470000004341e-06
        rotation 0.9999999999999631 -1.9216363728903724e-07 1.9221816916878313e-07 1.57079998822845
        children [
          USE WHEELSIZE
        ]
        name "Wheel4"
        boundingObject USE WHEELSIZE
        physics USE WheelPhysics
      }
    }
  ]
  name "Robot12"
  boundingObject USE BODY
  physics Physics {
  }
  controller "drive_robot"
  customData "green,9,0"
}
Robot {
  translation 5.03 -1.09 0.08881
  rotation 7.628487834490508e-08 -1.1493395721791664e-06 0.9999999999993368 1.570800000003245
  children [
    DistanceSensor {
    }
    DEF BODY Shape {
      appearance PBRAppearance {
        baseColor 0 0.666667 0
        metalness 0
      }
      geometry Box {
        size 0.4 0.2 0.1
      }
    }
    HingeJoint {
      jointParameters HingeJointParameters {
        position -3.758758255755347e-07
        axis 0 1 0
        anchor 0.1 0.12 0
      }
      device [
        RotationalMotor {
          name "Wheel1"
        }
      ]
      endPoint Solid {
        translation 0.1 0.12 0
        rotation 0.9999999999999647 -1.8790074833068145e-07 1.8790143596283312e-07 1.5707999856069161
        children [
          DEF WHEELSIZE Shape {
            appearance PBRAppearance {
              baseColor 0 0 0
              metalness 0
            }
            geometry Cylinder {
              height 0.04
              radius 0.1
            }
          }
        ]
        name "Wheel1"
        boundingObject USE WHEELSIZE
        physics DEF WheelPhysics Physics {
          density -1
          mass 1
        }
      }
    }
    HingeJoint {
      jointParameters HingeJointParameters {
        position -6.684814028052229e-07
        axis 0 1 0
        anchor 0.1 -0.12 0
      }
      device [
        RotationalMotor {
          name "Wheel2"
        }
      ]
      endPoint Solid {
        translation 0.09999999999756642 -0.12 3.640220000001277e-06
        rotation 0.9999999999998924 -3.2765733789223654e-07 3.277112492656089e-07 1.5707999857593695
        children [
          USE WHEELSIZE
        ]
        name "Wheel2"
        boundingObject USE WHEELSIZE
        physics USE WheelPhysics
      }
    }
    HingeJoint {
      jointParameters HingeJointParameters {
        position -6.702059438080107e-07
        axis 0 1 0
        anchor -0.1 -0.12 0
      }
      device [
        RotationalMotor {
          name "Wheel3"
        }
      ]
      endPoint Solid {
        translation -0.1 -0.12 0
        rotation 0.9999999999998875 -3.3506529844963604e-07 3.350665230656247e-07 1.5707999835204052
        children [
          USE WHEELSIZE
        ]
        name "Wheel3"
        boundingObject USE WHEELSIZE
        physics USE WheelPhysics
      }
    }
    HingeJoint {
      jointParameters HingeJointParameters {
        position -3.7415394788342553e-07
        axis 0 1 0
        anchor -0.1 0.12 0
      }
      device [
        RotationalMotor {
          name "Wheel4"
        }
      ]
      endPoint Solid {
        translation -0.1000000000015456 0.12 4.130470000004341e-06
        rotation 0.9999999999999631 -1.9216363728903724e-07 1.9221816916878313e-07 1.57079998822845
        children [
          USE WHEELSIZE
        ]
        name "Wheel4"
        boundingObject USE WHEELSIZE
        physics USE WheelPhysics
      }
    }
  ]
  name "Robot13"
  boundingObject USE BODY
  physics Physics {
  }
  controller "drive_robot"
  customData "green,5,1"
}
Robot {
  translation 12.01 -9.02 0.0888069
  rotation 7.628487834490508e-08 -1.1493395721791664e-06 0.9999999999993368 1.570800000003245
  children [
    DistanceSensor {
    }
    DEF BODY Shape {
      appearance PBRAppearance {
        baseColor 0 0.666667 0
        metalness 0
      }
      geometry Box {
        size 0.4 0.2 0.1
      }
    }
    HingeJoint {
      jointParameters HingeJointParameters {
        position -3.758758255755347e-07
        axis 0 1 0
        anchor 0.1 0.12 0
      }
      device [
        RotationalMotor {
          name "Wheel1"
        }
      ]
      endPoint Solid {
        translation 0.1 0.12 0
        rotation 0.9999999999999647 -1.8790074833068145e-07 1.8790143596283312e-07 1.5707999856069161
        children [
          DEF WHEELSIZE Shape {
            appearance PBRAppearance {
              baseColor 0 0 0
              metalness 0
            }
            geometry Cylinder {
              height 0.04
              radius 0.1
            }
          }
        ]
        name "Wheel1"
        boundingObject USE WHEELSIZE
        physics DEF WheelPhysics Physics {
          density -1
          mass 1
        }
      }
    }
    HingeJoint {
      jointParameters HingeJointParameters {
        position -6.684814028052229e-07
        axis 0 1 0
        anchor 0.1 -0.12 0
      }
      device [
        RotationalMotor {
          name "Wheel2"
        }
      ]
      endPoint Solid {
        translation 0.09999999999756642 -0.12 3.640220000001277e-06
        rotation 0.9999999999998924 -3.2765733789223654e-07 3.277112492656089e-07 1.5707999857593695
        children [
          USE WHEELSIZE
        ]
        name "Wheel2"
        boundingObject USE WHEELSIZE
        physics USE WheelPhysics
      }
    }
    HingeJoint {
      jointParameters HingeJointParameters {
        position -6.702059438080107e-07
        axis 0 1 0
        anchor -0.1 -0.12 0
      }
      device [
        RotationalMotor {
          name "Wheel3"
        }
      ]
      endPoint Solid {
        translation -0.1 -0.12 0
        rotation 0.9999999999998875 -3.3506529844963604e-07 3.350665230656247e-07 1.5707999835204052
        children [
          USE WHEELSIZE
        ]
        name "Wheel3"
        boundingObject USE WHEELSIZE
        physics USE WheelPhysics
      }
    }
    HingeJoint {
      jointParameters HingeJointParameters {
        position -3.7415394788342553e-07
        axis 0 1 0
        anchor -0.1 0.12 0
      }
      device [
        RotationalMotor {
          name "Wheel4"
        }
      ]
      endPoint Solid {
        translation -0.1000000000015456 0.12 4.130470000004341e-06
        rotation 0.9999999999999631 -1.9216363728903724e-07 1.9221816916878313e-07 1.57079998822845
        children [
          USE WHEELSIZE
        ]
        name "Wheel4"
        boundingObject USE WHEELSIZE
        physics USE WheelPhysics
      }
    }
  ]
  name "Robot14"
  boundingObject USE BODY
  physics Physics {
  }
  controller "drive_robot"
  customData "green,12,9"
}
